*** Starting uWSGI 2.0.17.1 (64bit) on [Thu Jan 17 15:17:03 2019] ***
compiled with version: 5.4.0 20160609 on 17 January 2019 07:08:11
os: Linux-4.4.0-117-generic #141-Ubuntu SMP Tue Mar 13 11:58:07 UTC 2018
nodename: iZwz9fs05owv1cc2dm7nomZ
machine: x86_64
clock source: unix
detected number of CPU cores: 1
current working directory: /var/www/AXF
writing pidfile to uwsgi.pid
detected binary path: /root/.virtualenvs/python1811/bin/uwsgi
!!! no internal routing support, rebuild with pcre support !!!
uWSGI running as root, you can use --uid/--gid/--chroot options
*** WARNING: you are running uWSGI as root !!! (use the --uid flag) *** 
chdir() to /var/www/AXF
*** WARNING: you are running uWSGI without its master process manager ***
your processes number limit is 3824
your memory page size is 4096 bytes
detected max file descriptor number: 65535
lock engine: pthread robust mutexes
thunder lock: disabled (you can enable it with --thunder-lock)
uWSGI http bound on 0.0.0.0:8090 fd 4
spawned uWSGI http 1 (pid: 20880)
uwsgi socket 0 bound to TCP address 127.0.0.1:35270 (port auto-assigned) fd 3
uWSGI running as root, you can use --uid/--gid/--chroot options
*** WARNING: you are running uWSGI as root !!! (use the --uid flag) *** 
Python version: 3.5.2 (default, Nov 12 2018, 13:43:14)  [GCC 5.4.0 20160609]
Python main interpreter initialized at 0x18ad3a0
uWSGI running as root, you can use --uid/--gid/--chroot options
*** WARNING: you are running uWSGI as root !!! (use the --uid flag) *** 
python threads support enabled
your server socket listen backlog is limited to 100 connections
your mercy for graceful operations on workers is 60 seconds
mapped 72904 bytes (71 KB) for 1 cores
*** Operational MODE: single process ***
WSGI app 0 (mountpoint='') ready in 0 seconds on interpreter 0x18ad3a0 pid: 20879 (default app)
uWSGI running as root, you can use --uid/--gid/--chroot options
*** WARNING: you are running uWSGI as root !!! (use the --uid flag) *** 
*** uWSGI is running in multiple interpreter mode ***
spawned uWSGI worker 1 (and the only) (pid: 20879, cores: 1)
*** Starting uWSGI 2.0.17.1 (64bit) on [Thu Jan 17 15:59:02 2019] ***
compiled with version: 5.4.0 20160609 on 17 January 2019 07:08:11
os: Linux-4.4.0-117-generic #141-Ubuntu SMP Tue Mar 13 11:58:07 UTC 2018
nodename: iZwz9fs05owv1cc2dm7nomZ
machine: x86_64
clock source: unix
detected number of CPU cores: 1
current working directory: /var/www/AXF
writing pidfile to uwsgi.pid
detected binary path: /root/.virtualenvs/python1811/bin/uwsgi
!!! no internal routing support, rebuild with pcre support !!!
uWSGI running as root, you can use --uid/--gid/--chroot options
*** WARNING: you are running uWSGI as root !!! (use the --uid flag) *** 
chdir() to /var/www/AXF
*** WARNING: you are running uWSGI without its master process manager ***
your processes number limit is 3824
your memory page size is 4096 bytes
detected max file descriptor number: 65535
lock engine: pthread robust mutexes
thunder lock: disabled (you can enable it with --thunder-lock)
uwsgi socket 0 bound to TCP address 0.0.0.0:8000 fd 3
uWSGI running as root, you can use --uid/--gid/--chroot options
*** WARNING: you are running uWSGI as root !!! (use the --uid flag) *** 
Python version: 3.5.2 (default, Nov 12 2018, 13:43:14)  [GCC 5.4.0 20160609]
Python main interpreter initialized at 0x1b0a2b0
uWSGI running as root, you can use --uid/--gid/--chroot options
*** WARNING: you are running uWSGI as root !!! (use the --uid flag) *** 
python threads support enabled
your server socket listen backlog is limited to 100 connections
your mercy for graceful operations on workers is 60 seconds
mapped 72904 bytes (71 KB) for 1 cores
*** Operational MODE: single process ***
WSGI app 0 (mountpoint='') ready in 0 seconds on interpreter 0x1b0a2b0 pid: 20957 (default app)
uWSGI running as root, you can use --uid/--gid/--chroot options
*** WARNING: you are running uWSGI as root !!! (use the --uid flag) *** 
*** uWSGI is running in multiple interpreter mode ***
spawned uWSGI worker 1 (and the only) (pid: 20957, cores: 1)
Traceback (most recent call last):
  File "/root/.virtualenvs/python1811/lib/python3.5/site-packages/django/core/handlers/wsgi.py", line 156, in __call__
    request = self.request_class(environ)
  File "/root/.virtualenvs/python1811/lib/python3.5/site-packages/django/core/handlers/wsgi.py", line 97, in __init__
    self.method = environ['REQUEST_METHOD'].upper()
KeyError: 'REQUEST_METHOD'
[pid: 20957|app: 0|req: 1/1]  () {16 vars in 469 bytes} [Thu Jan 17 07:59:20 2019]   => generated 0 bytes in 0 msecs ( 500) 0 headers in 0 bytes (0 switches on core 0)
Traceback (most recent call last):
  File "/root/.virtualenvs/python1811/lib/python3.5/site-packages/django/core/handlers/wsgi.py", line 156, in __call__
    request = self.request_class(environ)
  File "/root/.virtualenvs/python1811/lib/python3.5/site-packages/django/core/handlers/wsgi.py", line 97, in __init__
    self.method = environ['REQUEST_METHOD'].upper()
KeyError: 'REQUEST_METHOD'
[pid: 20957|app: 0|req: 2/2]  () {16 vars in 469 bytes} [Thu Jan 17 07:59:36 2019]   => generated 0 bytes in 0 msecs ( 500) 0 headers in 0 bytes (0 switches on core 0)
[pid: 20957|app: 0|req: 3/3] 113.87.161.170 () {42 vars in 746 bytes} [Thu Jan 17 08:03:18 2019] GET /axf/ => generated 20349 bytes in 48 msecs (HTTP/1.1 200) 3 headers in 111 bytes (1 switches on core 0)
[pid: 20957|app: 0|req: 4/4] 113.87.161.170 () {42 vars in 746 bytes} [Thu Jan 17 08:03:35 2019] GET /axf/ => generated 20349 bytes in 20 msecs (HTTP/1.1 200) 3 headers in 111 bytes (1 switches on core 0)
[pid: 20957|app: 0|req: 5/5] 113.87.161.170 () {42 vars in 746 bytes} [Thu Jan 17 08:03:44 2019] GET /axf/ => generated 20349 bytes in 21 msecs (HTTP/1.1 200) 3 headers in 111 bytes (1 switches on core 0)
[pid: 20957|app: 0|req: 6/6] 113.87.161.170 () {42 vars in 746 bytes} [Thu Jan 17 08:03:53 2019] GET /axf/ => generated 20349 bytes in 21 msecs (HTTP/1.1 200) 3 headers in 111 bytes (1 switches on core 0)
[pid: 20957|app: 0|req: 7/7] 113.87.161.170 () {42 vars in 772 bytes} [Thu Jan 17 08:04:07 2019] GET /axf/ => generated 20349 bytes in 18 msecs (HTTP/1.1 200) 3 headers in 111 bytes (1 switches on core 0)
[pid: 20957|app: 0|req: 8/8] 113.87.161.170 () {44 vars in 807 bytes} [Thu Jan 17 08:04:20 2019] GET /axf/market/0/1/ => generated 10631 bytes in 24 msecs (HTTP/1.1 200) 4 headers in 196 bytes (1 switches on core 0)
[pid: 20957|app: 0|req: 9/9] 113.87.161.170 () {46 vars in 845 bytes} [Thu Jan 17 08:04:25 2019] GET /axf/ => generated 20349 bytes in 33 msecs (HTTP/1.1 200) 3 headers in 111 bytes (1 switches on core 0)
[pid: 20957|app: 0|req: 10/10] 113.87.161.170 () {44 vars in 762 bytes} [Thu Jan 17 08:04:25 2019] GET /axf/cart/ => generated 0 bytes in 1 msecs (HTTP/1.1 302) 5 headers in 147 bytes (1 switches on core 0)
[pid: 20957|app: 0|req: 11/11] 113.87.161.170 () {44 vars in 764 bytes} [Thu Jan 17 08:04:25 2019] GET /axf/login/ => generated 2411 bytes in 5 msecs (HTTP/1.1 200) 5 headers in 278 bytes (1 switches on core 0)
[pid: 20957|app: 0|req: 12/12] 113.87.161.170 () {44 vars in 757 bytes} [Thu Jan 17 08:04:28 2019] GET /axf/mine/ => generated 5815 bytes in 7 msecs (HTTP/1.1 200) 4 headers in 124 bytes (1 switches on core 0)
Invalid HTTP_HOST header: ''. The domain name provided is not valid according to RFC 1034/1035.
[pid: 20957|app: 0|req: 13/13] 200.163.38.195 () {26 vars in 269 bytes} [Thu Jan 17 08:04:38 2019] GET / => generated 55080 bytes in 46 msecs (HTTP/1.0 400) 1 headers in 53 bytes (1 switches on core 0)
[pid: 20957|app: 0|req: 14/14] 113.87.161.170 () {44 vars in 756 bytes} [Thu Jan 17 08:04:44 2019] GET /axf/home/ => generated 20349 bytes in 22 msecs (HTTP/1.1 200) 3 headers in 111 bytes (1 switches on core 0)
Not Found: /
[pid: 20957|app: 0|req: 15/15] 113.87.160.245 () {42 vars in 741 bytes} [Thu Jan 17 08:07:49 2019] GET / => generated 2019 bytes in 5 msecs (HTTP/1.1 404) 3 headers in 102 bytes (1 switches on core 0)
Not Found: /favicon.ico
[pid: 20957|app: 0|req: 16/16] 113.87.160.245 () {40 vars in 728 bytes} [Thu Jan 17 08:07:49 2019] GET /favicon.ico => generated 2070 bytes in 4 msecs (HTTP/1.1 404) 3 headers in 102 bytes (1 switches on core 0)
[pid: 20957|app: 0|req: 17/17] 113.87.160.245 () {42 vars in 747 bytes} [Thu Jan 17 08:07:55 2019] GET /axf => generated 0 bytes in 0 msecs (HTTP/1.1 301) 3 headers in 110 bytes (1 switches on core 0)
[pid: 20957|app: 0|req: 18/18] 113.87.160.245 () {42 vars in 749 bytes} [Thu Jan 17 08:07:55 2019] GET /axf/ => generated 20349 bytes in 21 msecs (HTTP/1.1 200) 3 headers in 111 bytes (1 switches on core 0)
[pid: 20957|app: 0|req: 19/19] 113.87.160.245 () {40 vars in 623 bytes} [Thu Jan 17 08:08:02 2019] GET /axf/home/ => generated 20349 bytes in 23 msecs (HTTP/1.1 200) 3 headers in 111 bytes (1 switches on core 0)
Not Found: /favicon.ico
[pid: 20957|app: 0|req: 20/20] 113.87.161.170 () {38 vars in 592 bytes} [Thu Jan 17 08:08:03 2019] GET /favicon.ico => generated 2070 bytes in 4 msecs (HTTP/1.1 404) 3 headers in 102 bytes (1 switches on core 0)
[pid: 20957|app: 0|req: 21/21] 113.87.161.170 () {44 vars in 780 bytes} [Thu Jan 17 08:08:13 2019] GET /axf/ => generated 20349 bytes in 21 msecs (HTTP/1.1 200) 3 headers in 111 bytes (1 switches on core 0)
[pid: 20957|app: 0|req: 22/22] 113.87.161.170 () {48 vars in 894 bytes} [Thu Jan 17 08:08:26 2019] GET /axf/cart/ => generated 0 bytes in 1 msecs (HTTP/1.1 302) 5 headers in 147 bytes (1 switches on core 0)
[pid: 20957|app: 0|req: 23/23] 113.87.161.170 () {48 vars in 896 bytes} [Thu Jan 17 08:08:27 2019] GET /axf/login/ => generated 2411 bytes in 6 msecs (HTTP/1.1 200) 5 headers in 278 bytes (1 switches on core 0)
[pid: 20957|app: 0|req: 24/24] 113.87.161.170 () {44 vars in 798 bytes} [Thu Jan 17 08:08:50 2019] GET /axf/mine/ => generated 5815 bytes in 7 msecs (HTTP/1.1 200) 4 headers in 124 bytes (1 switches on core 0)
[pid: 20957|app: 0|req: 25/25] 113.87.161.170 () {44 vars in 811 bytes} [Thu Jan 17 08:08:52 2019] GET /axf/register/ => generated 3238 bytes in 6 msecs (HTTP/1.1 200) 5 headers in 278 bytes (1 switches on core 0)
[pid: 20957|app: 0|req: 26/26] 113.87.161.170 () {44 vars in 803 bytes} [Thu Jan 17 08:09:03 2019] GET /axf/home/ => generated 20349 bytes in 20 msecs (HTTP/1.1 200) 3 headers in 111 bytes (1 switches on core 0)
[pid: 20957|app: 0|req: 27/27] 113.87.161.170 () {42 vars in 667 bytes} [Thu Jan 17 08:09:04 2019] GET /axf/mine/ => generated 5815 bytes in 6 msecs (HTTP/1.1 200) 4 headers in 124 bytes (1 switches on core 0)
[pid: 20957|app: 0|req: 28/28] 113.87.161.170 () {42 vars in 667 bytes} [Thu Jan 17 08:09:08 2019] GET /axf/cart/ => generated 0 bytes in 1 msecs (HTTP/1.1 302) 5 headers in 147 bytes (1 switches on core 0)
[pid: 20957|app: 0|req: 29/29] 113.87.161.170 () {42 vars in 669 bytes} [Thu Jan 17 08:09:08 2019] GET /axf/login/ => generated 2411 bytes in 8 msecs (HTTP/1.1 200) 5 headers in 278 bytes (1 switches on core 0)
[pid: 20957|app: 0|req: 30/30] 113.87.161.170 () {42 vars in 714 bytes} [Thu Jan 17 08:09:14 2019] GET /axf/login/ => generated 2411 bytes in 6 msecs (HTTP/1.1 200) 5 headers in 278 bytes (1 switches on core 0)
[pid: 20957|app: 0|req: 31/31] 113.87.161.170 () {42 vars in 714 bytes} [Thu Jan 17 08:09:28 2019] GET /axf/login/ => generated 2411 bytes in 6 msecs (HTTP/1.1 200) 5 headers in 278 bytes (1 switches on core 0)
[pid: 20957|app: 0|req: 32/32] 113.87.161.170 () {44 vars in 815 bytes} [Thu Jan 17 08:09:34 2019] GET /axf/market/0/1/ => generated 10631 bytes in 18 msecs (HTTP/1.1 200) 4 headers in 125 bytes (1 switches on core 0)
[pid: 20957|app: 0|req: 33/33] 113.87.161.170 () {44 vars in 782 bytes} [Thu Jan 17 08:09:36 2019] GET /axf/addcart/?goodsid=495 => generated 61 bytes in 1 msecs (HTTP/1.1 200) 4 headers in 114 bytes (1 switches on core 0)
[pid: 20957|app: 0|req: 34/34] 113.87.161.170 () {44 vars in 809 bytes} [Thu Jan 17 08:09:36 2019] GET /axf/login => generated 0 bytes in 0 msecs (HTTP/1.1 301) 3 headers in 116 bytes (1 switches on core 0)
[pid: 20957|app: 0|req: 35/35] 113.87.161.170 () {44 vars in 811 bytes} [Thu Jan 17 08:09:36 2019] GET /axf/login/ => generated 2411 bytes in 6 msecs (HTTP/1.1 200) 5 headers in 278 bytes (1 switches on core 0)
[pid: 20957|app: 0|req: 36/36] 113.87.161.170 () {42 vars in 714 bytes} [Thu Jan 17 08:09:37 2019] GET /axf/login/ => generated 2411 bytes in 6 msecs (HTTP/1.1 200) 5 headers in 278 bytes (1 switches on core 0)
[pid: 20957|app: 0|req: 37/37] 113.87.161.170 () {44 vars in 809 bytes} [Thu Jan 17 08:09:39 2019] GET /axf/home/ => generated 20349 bytes in 28 msecs (HTTP/1.1 200) 3 headers in 111 bytes (1 switches on core 0)
[pid: 20957|app: 0|req: 38/38] 113.87.161.170 () {44 vars in 803 bytes} [Thu Jan 17 08:09:45 2019] GET /axf/mine/ => generated 5815 bytes in 6 msecs (HTTP/1.1 200) 4 headers in 124 bytes (1 switches on core 0)
[pid: 20957|app: 0|req: 39/39] 113.87.161.170 () {48 vars in 896 bytes} [Thu Jan 17 08:09:46 2019] GET /axf/login/ => generated 2411 bytes in 6 msecs (HTTP/1.1 200) 5 headers in 278 bytes (1 switches on core 0)
[pid: 20957|app: 0|req: 40/40] 113.87.161.170 () {48 vars in 876 bytes} [Thu Jan 17 08:09:46 2019] POST /axf/login/ => generated 0 bytes in 16 msecs (HTTP/1.1 302) 6 headers in 277 bytes (1 switches on core 0)
[pid: 20957|app: 0|req: 41/41] 113.87.161.170 () {44 vars in 801 bytes} [Thu Jan 17 08:09:47 2019] GET /axf/mine/ => generated 5847 bytes in 12 msecs (HTTP/1.1 200) 4 headers in 124 bytes (1 switches on core 0)
[pid: 20957|app: 0|req: 42/42] 113.87.161.170 () {44 vars in 800 bytes} [Thu Jan 17 08:09:51 2019] GET /axf/cart/ => generated 6787 bytes in 22 msecs (HTTP/1.1 200) 4 headers in 124 bytes (1 switches on core 0)
[pid: 20957|app: 0|req: 43/43] 113.87.161.170 () {42 vars in 784 bytes} [Thu Jan 17 08:09:52 2019] GET /axf/login/ => generated 2411 bytes in 6 msecs (HTTP/1.1 200) 5 headers in 278 bytes (1 switches on core 0)
[pid: 20957|app: 0|req: 44/44] 113.87.161.170 () {44 vars in 785 bytes} [Thu Jan 17 08:09:56 2019] GET /axf/changecartstatus/?cartid=2 => generated 78 bytes in 8 msecs (HTTP/1.1 200) 3 headers in 100 bytes (1 switches on core 0)
[pid: 20957|app: 0|req: 45/45] 113.87.161.170 () {44 vars in 785 bytes} [Thu Jan 17 08:09:57 2019] GET /axf/changecartstatus/?cartid=3 => generated 78 bytes in 14 msecs (HTTP/1.1 200) 3 headers in 100 bytes (1 switches on core 0)
[pid: 20957|app: 0|req: 46/46] 113.87.160.245 () {48 vars in 900 bytes} [Thu Jan 17 08:10:07 2019] GET /axf/mine/ => generated 5815 bytes in 7 msecs (HTTP/1.1 200) 4 headers in 124 bytes (1 switches on core 0)
[pid: 20957|app: 0|req: 47/47] 113.87.160.245 () {48 vars in 899 bytes} [Thu Jan 17 08:11:42 2019] GET /axf/home/ => generated 20349 bytes in 21 msecs (HTTP/1.1 200) 3 headers in 111 bytes (1 switches on core 0)
Not Found: /.git/config
[pid: 20957|app: 0|req: 48/48] 89.248.174.141 () {30 vars in 448 bytes} [Thu Jan 17 08:16:42 2019] GET /.git/config => generated 2070 bytes in 4 msecs (HTTP/1.1 404) 3 headers in 102 bytes (1 switches on core 0)
Invalid HTTP_HOST header: ''. The domain name provided is not valid according to RFC 1034/1035.
[pid: 20957|app: 0|req: 49/49] 191.96.110.5 () {30 vars in 363 bytes} [Thu Jan 17 08:35:28 2019] GET / => generated 55382 bytes in 44 msecs (HTTP/1.0 400) 1 headers in 53 bytes (1 switches on core 0)
Not Found: /ccvv
[pid: 20957|app: 0|req: 50/50] 71.6.202.198 () {34 vars in 421 bytes} [Thu Jan 17 08:50:55 2019] GET /ccvv => generated 2049 bytes in 4 msecs (HTTP/1.1 404) 3 headers in 102 bytes (1 switches on core 0)
Not Found: /api/v1/citylist/
[pid: 20957|app: 0|req: 51/51] 113.92.94.136 () {42 vars in 793 bytes} [Thu Jan 17 08:57:13 2019] GET /api/v1/citylist/ => generated 2085 bytes in 4 msecs (HTTP/1.1 404) 3 headers in 102 bytes (1 switches on core 0)
invalid request block size: 21573 (max 4096)...skip
invalid request block size: 21573 (max 4096)...skip
Not Found: /
[pid: 20957|app: 0|req: 52/52] 103.224.100.66 () {32 vars in 449 bytes} [Thu Jan 17 09:04:47 2019] GET / => generated 2022 bytes in 4 msecs (HTTP/1.1 404) 3 headers in 102 bytes (1 switches on core 0)
Not Found: /
[pid: 20957|app: 0|req: 53/53] 103.91.82.35 () {32 vars in 447 bytes} [Thu Jan 17 09:19:08 2019] GET / => generated 2022 bytes in 4 msecs (HTTP/1.1 404) 3 headers in 102 bytes (1 switches on core 0)
invalid request block size: 21573 (max 4096)...skip
invalid request block size: 21573 (max 4096)...skip
Not Found: /favicon.ico
[pid: 20957|app: 0|req: 54/54] 183.178.4.244 () {48 vars in 858 bytes} [Thu Jan 17 09:48:16 2019] GET /favicon.ico => generated 2070 bytes in 4 msecs (HTTP/1.1 404) 3 headers in 102 bytes (1 switches on core 0)
Not Found: /cache/global/img/gs.gif
[pid: 20957|app: 0|req: 55/55] 80.82.70.187 () {32 vars in 420 bytes} [Thu Jan 17 10:06:00 2019] GET /cache/global/img/gs.gif => generated 2108 bytes in 4 msecs (HTTP/1.1 404) 3 headers in 102 bytes (1 switches on core 0)
Not Found: /echo.php
[pid: 20957|app: 0|req: 56/56] 139.162.88.63 () {32 vars in 407 bytes} [Thu Jan 17 10:08:25 2019] GET /echo.php?info=1234567890 => generated 2084 bytes in 4 msecs (HTTP/1.1 404) 3 headers in 102 bytes (1 switches on core 0)
Not Found: /
[pid: 20957|app: 0|req: 57/57] 178.79.88.5 () {32 vars in 446 bytes} [Thu Jan 17 10:29:12 2019] GET / => generated 2022 bytes in 4 msecs (HTTP/1.1 404) 3 headers in 102 bytes (1 switches on core 0)
Not Found: /
[pid: 20957|app: 0|req: 58/58] 138.118.100.139 () {32 vars in 450 bytes} [Thu Jan 17 10:34:51 2019] GET / => generated 2022 bytes in 4 msecs (HTTP/1.1 404) 3 headers in 102 bytes (1 switches on core 0)
invalid request block size: 21573 (max 4096)...skip
Not Found: /.git/config
[pid: 20957|app: 0|req: 59/59] 89.248.174.141 () {30 vars in 448 bytes} [Thu Jan 17 11:07:15 2019] GET /.git/config => generated 2070 bytes in 6 msecs (HTTP/1.1 404) 3 headers in 102 bytes (1 switches on core 0)
Not Found: /
[pid: 20957|app: 0|req: 60/60] 103.100.128.51 () {32 vars in 450 bytes} [Thu Jan 17 11:43:42 2019] GET / => generated 2022 bytes in 4 msecs (HTTP/1.1 404) 3 headers in 102 bytes (1 switches on core 0)
Not Found: /
[pid: 20957|app: 0|req: 61/61] 186.192.16.180 () {32 vars in 450 bytes} [Thu Jan 17 11:54:17 2019] GET / => generated 2022 bytes in 4 msecs (HTTP/1.1 404) 3 headers in 102 bytes (1 switches on core 0)
Not Found: /
[pid: 20957|app: 0|req: 62/62] 104.128.144.131 () {32 vars in 379 bytes} [Thu Jan 17 12:15:18 2019] GET / => generated 2019 bytes in 4 msecs (HTTP/1.0 404) 3 headers in 102 bytes (1 switches on core 0)
Not Found: /redirect.php
[pid: 20957|app: 0|req: 63/63] 104.128.144.131 () {32 vars in 404 bytes} [Thu Jan 17 12:15:26 2019] HEAD /redirect.php => generated 2074 bytes in 4 msecs (HTTP/1.0 404) 3 headers in 102 bytes (1 switches on core 0)
Not Found: /robots.txt
[pid: 20957|app: 0|req: 64/64] 54.36.148.103 () {34 vars in 458 bytes} [Thu Jan 17 12:47:39 2019] GET /robots.txt => generated 2073 bytes in 3 msecs (HTTP/1.1 404) 3 headers in 102 bytes (1 switches on core 0)
Not Found: /company
[pid: 20957|app: 0|req: 65/65] 54.36.148.11 () {34 vars in 451 bytes} [Thu Jan 17 12:47:45 2019] GET /company => generated 2064 bytes in 4 msecs (HTTP/1.1 404) 3 headers in 102 bytes (1 switches on core 0)
Not Found: /
[pid: 20957|app: 0|req: 66/66] 177.87.158.214 () {32 vars in 450 bytes} [Thu Jan 17 12:48:11 2019] GET / => generated 2022 bytes in 4 msecs (HTTP/1.1 404) 3 headers in 102 bytes (1 switches on core 0)
Not Found: /index.asp
[pid: 20957|app: 0|req: 67/67] 111.162.146.214 () {34 vars in 488 bytes} [Thu Jan 17 13:05:25 2019] GET /index.asp => generated 2064 bytes in 5 msecs (HTTP/1.1 404) 3 headers in 102 bytes (1 switches on core 0)
Not Found: /
[pid: 20957|app: 0|req: 68/68] 212.87.255.155 () {32 vars in 450 bytes} [Thu Jan 17 13:52:02 2019] GET / => generated 2022 bytes in 4 msecs (HTTP/1.1 404) 3 headers in 102 bytes (1 switches on core 0)
Not Found: /azenv.php
[pid: 20957|app: 0|req: 69/69] 95.213.177.125 () {40 vars in 695 bytes} [Thu Jan 17 13:54:24 2019] POST /azenv.php?auth=154773326481&a=PSCN&i=1883911939&p=80 => generated 2129 bytes in 4 msecs (HTTP/1.1 404) 3 headers in 102 bytes (1 switches on core 0)
Invalid HTTP_HOST header: ''. The domain name provided is not valid according to RFC 1034/1035.
[pid: 20957|app: 0|req: 70/70] 191.96.214.21 () {30 vars in 364 bytes} [Thu Jan 17 14:00:54 2019] GET / => generated 55383 bytes in 46 msecs (HTTP/1.0 400) 1 headers in 53 bytes (1 switches on core 0)
Not Found: /
[pid: 20957|app: 0|req: 71/71] 59.188.250.223 () {40 vars in 561 bytes} [Thu Jan 17 14:05:20 2019] GET / => generated 2019 bytes in 4 msecs (HTTP/1.1 404) 3 headers in 102 bytes (1 switches on core 0)
Not Found: /
[pid: 20957|app: 0|req: 72/72] 110.52.29.131 () {28 vars in 292 bytes} [Thu Jan 17 14:09:55 2019] GET / => generated 2019 bytes in 4 msecs (HTTP/1.1 404) 3 headers in 102 bytes (1 switches on core 0)
Not Found: /
[pid: 20957|app: 0|req: 73/73] 110.52.29.190 () {28 vars in 292 bytes} [Thu Jan 17 14:10:49 2019] GET / => generated 2019 bytes in 4 msecs (HTTP/1.1 404) 3 headers in 102 bytes (1 switches on core 0)
Not Found: /
[pid: 20957|app: 0|req: 74/74] 110.52.29.131 () {28 vars in 292 bytes} [Thu Jan 17 14:27:28 2019] GET / => generated 2019 bytes in 4 msecs (HTTP/1.1 404) 3 headers in 102 bytes (1 switches on core 0)
Not Found: /.git/config
[pid: 20957|app: 0|req: 75/75] 89.248.174.141 () {30 vars in 448 bytes} [Thu Jan 17 14:53:15 2019] GET /.git/config => generated 2070 bytes in 4 msecs (HTTP/1.1 404) 3 headers in 102 bytes (1 switches on core 0)
Not Found: /
[pid: 20957|app: 0|req: 76/76] 110.52.28.139 () {28 vars in 292 bytes} [Thu Jan 17 15:02:15 2019] GET / => generated 2019 bytes in 4 msecs (HTTP/1.1 404) 3 headers in 102 bytes (1 switches on core 0)
Not Found: /
[pid: 20957|app: 0|req: 77/77] 211.143.198.234 () {28 vars in 294 bytes} [Thu Jan 17 16:07:37 2019] GET / => generated 2019 bytes in 4 msecs (HTTP/1.1 404) 3 headers in 102 bytes (1 switches on core 0)
Not Found: /
[pid: 20957|app: 0|req: 78/78] 83.240.113.57 () {32 vars in 448 bytes} [Thu Jan 17 16:22:05 2019] GET / => generated 2022 bytes in 4 msecs (HTTP/1.1 404) 3 headers in 102 bytes (1 switches on core 0)
Not Found: /
[pid: 20957|app: 0|req: 79/79] 110.52.28.139 () {28 vars in 292 bytes} [Thu Jan 17 16:53:49 2019] GET / => generated 2019 bytes in 4 msecs (HTTP/1.1 404) 3 headers in 102 bytes (1 switches on core 0)
Not Found: /.git/config
[pid: 20957|app: 0|req: 80/80] 89.248.174.141 () {30 vars in 448 bytes} [Thu Jan 17 17:21:31 2019] GET /.git/config => generated 2070 bytes in 4 msecs (HTTP/1.1 404) 3 headers in 102 bytes (1 switches on core 0)
Not Found: /
[pid: 20957|app: 0|req: 81/81] 60.191.38.77 () {34 vars in 444 bytes} [Thu Jan 17 17:25:19 2019] GET / => generated 2024 bytes in 4 msecs (HTTP/1.1 404) 3 headers in 102 bytes (1 switches on core 0)
invalid request block size: 21573 (max 4096)...skip
Not Found: /
[pid: 20957|app: 0|req: 82/82] 79.105.117.102 () {32 vars in 448 bytes} [Thu Jan 17 18:11:50 2019] GET / => generated 2022 bytes in 4 msecs (HTTP/1.1 404) 3 headers in 102 bytes (1 switches on core 0)
Not Found: /
[pid: 20957|app: 0|req: 83/83] 60.191.38.77 () {34 vars in 445 bytes} [Thu Jan 17 18:12:50 2019] GET / => generated 2025 bytes in 4 msecs (HTTP/1.1 404) 3 headers in 102 bytes (1 switches on core 0)
Not Found: /.git/config
[pid: 20957|app: 0|req: 84/84] 89.248.174.141 () {30 vars in 448 bytes} [Thu Jan 17 18:35:02 2019] GET /.git/config => generated 2070 bytes in 4 msecs (HTTP/1.1 404) 3 headers in 102 bytes (1 switches on core 0)
Invalid HTTP_HOST header: ''. The domain name provided is not valid according to RFC 1034/1035.
[pid: 20957|app: 0|req: 85/85] 191.101.128.9 () {30 vars in 364 bytes} [Thu Jan 17 20:01:29 2019] GET / => generated 55383 bytes in 46 msecs (HTTP/1.0 400) 1 headers in 53 bytes (1 switches on core 0)
Not Found: /
[pid: 20957|app: 0|req: 86/86] 101.132.177.30 () {34 vars in 489 bytes} [Thu Jan 17 20:04:34 2019] GET / => generated 2024 bytes in 4 msecs (HTTP/1.1 404) 3 headers in 102 bytes (1 switches on core 0)
-- unavailable modifier requested: 3 --
Not Found: /cache/global/img/gs.gif
[pid: 20957|app: 0|req: 87/88] 80.82.70.187 () {32 vars in 420 bytes} [Thu Jan 17 20:06:59 2019] GET /cache/global/img/gs.gif => generated 2108 bytes in 4 msecs (HTTP/1.1 404) 3 headers in 102 bytes (1 switches on core 0)
Not Found: /
[pid: 20957|app: 0|req: 88/89] 35.163.197.110 () {38 vars in 629 bytes} [Thu Jan 17 20:18:15 2019] GET / => generated 2024 bytes in 4 msecs (HTTP/1.1 404) 3 headers in 102 bytes (1 switches on core 0)
Not Found: /
[pid: 20957|app: 0|req: 89/90] 146.88.240.128 () {40 vars in 465 bytes} [Thu Jan 17 21:33:44 2019] POST / => generated 2020 bytes in 4 msecs (HTTP/1.1 404) 3 headers in 102 bytes (1 switches on core 0)
Not Found: /
[pid: 20957|app: 0|req: 90/91] 183.88.170.201 () {32 vars in 450 bytes} [Thu Jan 17 21:45:17 2019] GET / => generated 2022 bytes in 4 msecs (HTTP/1.1 404) 3 headers in 102 bytes (1 switches on core 0)
Not Found: /.git/config
[pid: 20957|app: 0|req: 91/92] 89.248.174.141 () {30 vars in 448 bytes} [Thu Jan 17 22:08:24 2019] GET /.git/config => generated 2070 bytes in 4 msecs (HTTP/1.1 404) 3 headers in 102 bytes (1 switches on core 0)
Not Found: /
[pid: 20957|app: 0|req: 92/93] 2.179.119.54 () {32 vars in 447 bytes} [Thu Jan 17 22:44:37 2019] GET / => generated 2022 bytes in 4 msecs (HTTP/1.1 404) 3 headers in 102 bytes (1 switches on core 0)
Not Found: /
[pid: 20957|app: 0|req: 93/94] 115.238.55.23 () {32 vars in 424 bytes} [Thu Jan 17 23:00:44 2019] GET / => generated 2024 bytes in 4 msecs (HTTP/1.1 404) 3 headers in 102 bytes (1 switches on core 0)
-- unavailable modifier requested: 4 --
invalid request block size: 21573 (max 4096)...skip
Not Found: /404/search_children.js
[pid: 20957|app: 0|req: 94/96] 120.132.3.65 () {34 vars in 499 bytes} [Thu Jan 17 23:05:17 2019] GET /404/search_children.js => generated 2102 bytes in 4 msecs (HTTP/1.1 404) 3 headers in 102 bytes (1 switches on core 0)
Not Found: /azenv.php
[pid: 20957|app: 0|req: 95/97] 95.213.177.126 () {40 vars in 694 bytes} [Thu Jan 17 23:32:41 2019] POST /azenv.php?auth=154776796141&a=PSCN&i=1883911939&p=80 => generated 2129 bytes in 4 msecs (HTTP/1.1 404) 3 headers in 102 bytes (1 switches on core 0)
Not Found: /.git/config
[pid: 20957|app: 0|req: 96/98] 89.248.174.141 () {30 vars in 448 bytes} [Fri Jan 18 00:19:22 2019] GET /.git/config => generated 2070 bytes in 4 msecs (HTTP/1.1 404) 3 headers in 102 bytes (1 switches on core 0)
Not Found: /
[pid: 20957|app: 0|req: 97/99] 103.84.143.130 () {32 vars in 450 bytes} [Fri Jan 18 00:35:23 2019] GET / => generated 2022 bytes in 4 msecs (HTTP/1.1 404) 3 headers in 102 bytes (1 switches on core 0)
Not Found: /
[pid: 20957|app: 0|req: 98/100] 66.102.6.26 () {38 vars in 612 bytes} [Fri Jan 18 00:54:31 2019] GET / => generated 2019 bytes in 4 msecs (HTTP/1.1 404) 3 headers in 102 bytes (1 switches on core 0)
Not Found: /api/v1/citylist/
[pid: 20957|app: 0|req: 99/101] 113.92.94.136 () {42 vars in 793 bytes} [Fri Jan 18 00:55:12 2019] GET /api/v1/citylist/ => generated 2085 bytes in 3 msecs (HTTP/1.1 404) 3 headers in 102 bytes (1 switches on core 0)
invalid request block size: 21573 (max 4096)...skip
invalid request block size: 21573 (max 4096)...skip
Not Found: /cache/global/img/gs.gif
[pid: 20957|app: 0|req: 100/102] 80.82.78.50 () {32 vars in 419 bytes} [Fri Jan 18 01:29:02 2019] GET /cache/global/img/gs.gif => generated 2108 bytes in 5 msecs (HTTP/1.1 404) 3 headers in 102 bytes (1 switches on core 0)
Not Found: /
[pid: 20957|app: 0|req: 101/103] 103.78.15.19 () {32 vars in 454 bytes} [Fri Jan 18 01:32:59 2019] GET / => generated 2022 bytes in 4 msecs (HTTP/1.1 404) 3 headers in 102 bytes (1 switches on core 0)
Not Found: /
[pid: 20957|app: 0|req: 102/104] 101.4.110.154 () {32 vars in 406 bytes} [Fri Jan 18 01:38:52 2019] GET / => generated 2019 bytes in 4 msecs (HTTP/1.1 404) 3 headers in 102 bytes (1 switches on core 0)
Not Found: /
[pid: 20957|app: 0|req: 103/105] 103.78.181.225 () {32 vars in 449 bytes} [Fri Jan 18 01:45:11 2019] GET / => generated 2022 bytes in 4 msecs (HTTP/1.1 404) 3 headers in 102 bytes (1 switches on core 0)
Not Found: /
[pid: 20957|app: 0|req: 104/106] 187.11.42.242 () {32 vars in 448 bytes} [Fri Jan 18 01:45:58 2019] GET / => generated 2022 bytes in 4 msecs (HTTP/1.1 404) 3 headers in 102 bytes (1 switches on core 0)
Not Found: /.git/config
[pid: 20957|app: 0|req: 105/107] 89.248.174.141 () {30 vars in 448 bytes} [Fri Jan 18 03:02:25 2019] GET /.git/config => generated 2070 bytes in 4 msecs (HTTP/1.1 404) 3 headers in 102 bytes (1 switches on core 0)
invalid request block size: 21573 (max 4096)...skip
Not Found: /robots.txt
[pid: 20957|app: 0|req: 106/108] 203.208.60.8 () {36 vars in 514 bytes} [Fri Jan 18 03:49:34 2019] GET /robots.txt => generated 2072 bytes in 4 msecs (HTTP/1.1 404) 3 headers in 102 bytes (1 switches on core 0)
Not Found: /home/
[pid: 20957|app: 0|req: 107/109] 203.208.60.74 () {38 vars in 583 bytes} [Fri Jan 18 03:49:34 2019] GET /home/ => generated 2057 bytes in 4 msecs (HTTP/1.1 404) 3 headers in 102 bytes (1 switches on core 0)
invalid request block size: 21573 (max 4096)...skip
Not Found: /
[pid: 20957|app: 0|req: 108/110] 112.27.29.190 () {34 vars in 415 bytes} [Fri Jan 18 04:46:42 2019] GET / => generated 2019 bytes in 4 msecs (HTTP/1.1 404) 3 headers in 102 bytes (1 switches on core 0)
Not Found: /.git/config
[pid: 20957|app: 0|req: 109/111] 89.248.174.141 () {30 vars in 448 bytes} [Fri Jan 18 05:57:05 2019] GET /.git/config => generated 2070 bytes in 4 msecs (HTTP/1.1 404) 3 headers in 102 bytes (1 switches on core 0)
Not Found: /cache/global/img/gs.gif
[pid: 20957|app: 0|req: 110/112] 80.82.70.187 () {32 vars in 420 bytes} [Fri Jan 18 06:14:25 2019] GET /cache/global/img/gs.gif => generated 2108 bytes in 4 msecs (HTTP/1.1 404) 3 headers in 102 bytes (1 switches on core 0)
Not Found: /
[pid: 20957|app: 0|req: 111/113] 205.205.150.16 () {32 vars in 415 bytes} [Fri Jan 18 06:19:53 2019] GET / => generated 2019 bytes in 4 msecs (HTTP/1.1 404) 3 headers in 102 bytes (1 switches on core 0)
Not Found: /
[pid: 20957|app: 0|req: 112/114] 205.205.150.16 () {32 vars in 415 bytes} [Fri Jan 18 06:28:07 2019] GET / => generated 2019 bytes in 4 msecs (HTTP/1.1 404) 3 headers in 102 bytes (1 switches on core 0)
Not Found: /axf/returenview/
[pid: 20957|app: 0|req: 113/115] 113.87.161.170 () {42 vars in 770 bytes} [Fri Jan 18 06:31:24 2019] GET /axf/returenview/ => generated 4308 bytes in 6 msecs (HTTP/1.1 404) 3 headers in 102 bytes (1 switches on core 0)
Not Found: /favicon.ico
[pid: 20957|app: 0|req: 114/116] 113.87.161.170 () {40 vars in 725 bytes} [Fri Jan 18 06:31:24 2019] GET /favicon.ico => generated 2070 bytes in 4 msecs (HTTP/1.1 404) 3 headers in 102 bytes (1 switches on core 0)
*** Starting uWSGI 2.0.17.1 (64bit) on [Fri Jan 18 14:32:28 2019] ***
compiled with version: 5.4.0 20160609 on 17 January 2019 07:08:11
os: Linux-4.4.0-117-generic #141-Ubuntu SMP Tue Mar 13 11:58:07 UTC 2018
nodename: iZwz9fs05owv1cc2dm7nomZ
machine: x86_64
clock source: unix
detected number of CPU cores: 1
current working directory: /var/www/AXF
writing pidfile to uwsgi.pid
detected binary path: /root/.virtualenvs/python1811/bin/uwsgi
!!! no internal routing support, rebuild with pcre support !!!
uWSGI running as root, you can use --uid/--gid/--chroot options
*** WARNING: you are running uWSGI as root !!! (use the --uid flag) *** 
chdir() to /var/www/AXF
*** WARNING: you are running uWSGI without its master process manager ***
your processes number limit is 3824
your memory page size is 4096 bytes
detected max file descriptor number: 65535
lock engine: pthread robust mutexes
thunder lock: disabled (you can enable it with --thunder-lock)
uwsgi socket 0 bound to TCP address 0.0.0.0:8000 fd 3
uWSGI running as root, you can use --uid/--gid/--chroot options
*** WARNING: you are running uWSGI as root !!! (use the --uid flag) *** 
Python version: 3.5.2 (default, Nov 12 2018, 13:43:14)  [GCC 5.4.0 20160609]
Python main interpreter initialized at 0x26a02a0
uWSGI running as root, you can use --uid/--gid/--chroot options
*** WARNING: you are running uWSGI as root !!! (use the --uid flag) *** 
python threads support enabled
your server socket listen backlog is limited to 100 connections
your mercy for graceful operations on workers is 60 seconds
mapped 72904 bytes (71 KB) for 1 cores
*** Operational MODE: single process ***
WSGI app 0 (mountpoint='') ready in 0 seconds on interpreter 0x26a02a0 pid: 22013 (default app)
uWSGI running as root, you can use --uid/--gid/--chroot options
*** WARNING: you are running uWSGI as root !!! (use the --uid flag) *** 
*** uWSGI is running in multiple interpreter mode ***
spawned uWSGI worker 1 (and the only) (pid: 22013, cores: 1)
Not Found: /axf/returenview/
[pid: 22013|app: 0|req: 1/1] 113.87.161.170 () {42 vars in 770 bytes} [Fri Jan 18 06:32:31 2019] GET /axf/returenview/ => generated 5055 bytes in 16 msecs (HTTP/1.1 404) 3 headers in 102 bytes (1 switches on core 0)
[pid: 22013|app: 0|req: 2/2] 113.87.161.170 () {42 vars in 768 bytes} [Fri Jan 18 06:32:42 2019] GET /axf/returnview/ => generated 0 bytes in 9 msecs (HTTP/1.1 302) 4 headers in 132 bytes (1 switches on core 0)
[pid: 22013|app: 0|req: 3/3] 113.87.161.170 () {42 vars in 756 bytes} [Fri Jan 18 06:32:42 2019] GET /axf/mine/ => generated 5847 bytes in 31 msecs (HTTP/1.1 200) 4 headers in 124 bytes (1 switches on core 0)
支付完成(服务端)
[pid: 22013|app: 0|req: 4/4] 113.87.161.170 () {42 vars in 766 bytes} [Fri Jan 18 06:33:05 2019] GET /axf/appnotify/ => generated 18 bytes in 1 msecs (HTTP/1.1 200) 3 headers in 100 bytes (1 switches on core 0)
invalid request block size: 21573 (max 4096)...skip
invalid request block size: 21573 (max 4096)...skip
Invalid HTTP_HOST header: ''. The domain name provided is not valid according to RFC 1034/1035.
[pid: 22013|app: 0|req: 5/5] 91.207.172.194 () {26 vars in 269 bytes} [Fri Jan 18 06:45:57 2019] GET / => generated 55080 bytes in 51 msecs (HTTP/1.0 400) 1 headers in 53 bytes (1 switches on core 0)
invalid request block size: 21573 (max 4096)...skip
*** Starting uWSGI 2.0.17.1 (64bit) on [Fri Jan 18 15:01:24 2019] ***
compiled with version: 5.4.0 20160609 on 17 January 2019 07:08:11
os: Linux-4.4.0-117-generic #141-Ubuntu SMP Tue Mar 13 11:58:07 UTC 2018
nodename: iZwz9fs05owv1cc2dm7nomZ
machine: x86_64
clock source: unix
detected number of CPU cores: 1
current working directory: /var/www/AXF
writing pidfile to uwsgi.pid
detected binary path: /root/.virtualenvs/python1811/bin/uwsgi
!!! no internal routing support, rebuild with pcre support !!!
uWSGI running as root, you can use --uid/--gid/--chroot options
*** WARNING: you are running uWSGI as root !!! (use the --uid flag) *** 
chdir() to /var/www/AXF
*** WARNING: you are running uWSGI without its master process manager ***
your processes number limit is 3824
your memory page size is 4096 bytes
detected max file descriptor number: 65535
lock engine: pthread robust mutexes
thunder lock: disabled (you can enable it with --thunder-lock)
uwsgi socket 0 bound to TCP address 0.0.0.0:8000 fd 3
uWSGI running as root, you can use --uid/--gid/--chroot options
*** WARNING: you are running uWSGI as root !!! (use the --uid flag) *** 
Python version: 3.5.2 (default, Nov 12 2018, 13:43:14)  [GCC 5.4.0 20160609]
Python main interpreter initialized at 0xc422a0
uWSGI running as root, you can use --uid/--gid/--chroot options
*** WARNING: you are running uWSGI as root !!! (use the --uid flag) *** 
python threads support enabled
your server socket listen backlog is limited to 100 connections
your mercy for graceful operations on workers is 60 seconds
mapped 72904 bytes (71 KB) for 1 cores
*** Operational MODE: single process ***
WSGI app 0 (mountpoint='') ready in 0 seconds on interpreter 0xc422a0 pid: 22031 (default app)
uWSGI running as root, you can use --uid/--gid/--chroot options
*** WARNING: you are running uWSGI as root !!! (use the --uid flag) *** 
*** uWSGI is running in multiple interpreter mode ***
spawned uWSGI worker 1 (and the only) (pid: 22031, cores: 1)
[pid: 22031|app: 0|req: 1/1] 113.87.161.170 () {42 vars in 746 bytes} [Fri Jan 18 07:01:30 2019] GET /axf/ => generated 20349 bytes in 324 msecs (HTTP/1.1 200) 3 headers in 111 bytes (1 switches on core 0)
[pid: 22031|app: 0|req: 2/2] 113.87.160.245 () {44 vars in 795 bytes} [Fri Jan 18 07:01:34 2019] GET /axf/cart/ => generated 7057 bytes in 31 msecs (HTTP/1.1 200) 4 headers in 124 bytes (1 switches on core 0)
[pid: 22031|app: 0|req: 3/3] 113.87.161.170 () {44 vars in 785 bytes} [Fri Jan 18 07:01:39 2019] GET /axf/changecartall/?isall=false => generated 60 bytes in 11 msecs (HTTP/1.1 200) 4 headers in 114 bytes (1 switches on core 0)
[pid: 22031|app: 0|req: 4/4] 113.87.161.170 () {44 vars in 785 bytes} [Fri Jan 18 07:01:40 2019] GET /axf/changecartstatus/?cartid=3 => generated 78 bytes in 14 msecs (HTTP/1.1 200) 3 headers in 100 bytes (1 switches on core 0)
[pid: 22031|app: 0|req: 5/5] 113.87.161.170 () {44 vars in 785 bytes} [Fri Jan 18 07:01:42 2019] GET /axf/changecartstatus/?cartid=2 => generated 78 bytes in 9 msecs (HTTP/1.1 200) 3 headers in 100 bytes (1 switches on core 0)
Internal Server Error: /axf/generateorder/
Traceback (most recent call last):
  File "/root/.virtualenvs/python1811/lib/python3.5/site-packages/django/db/backends/utils.py", line 65, in execute
    return self.cursor.execute(sql, params)
  File "/root/.virtualenvs/python1811/lib/python3.5/site-packages/django/db/backends/mysql/base.py", line 101, in execute
    return self.cursor.execute(query, args)
  File "/root/.virtualenvs/python1811/lib/python3.5/site-packages/pymysql/cursors.py", line 170, in execute
    result = self._query(query)
  File "/root/.virtualenvs/python1811/lib/python3.5/site-packages/pymysql/cursors.py", line 328, in _query
    conn.query(q)
  File "/root/.virtualenvs/python1811/lib/python3.5/site-packages/pymysql/connections.py", line 517, in query
    self._affected_rows = self._read_query_result(unbuffered=unbuffered)
  File "/root/.virtualenvs/python1811/lib/python3.5/site-packages/pymysql/connections.py", line 732, in _read_query_result
    result.read()
  File "/root/.virtualenvs/python1811/lib/python3.5/site-packages/pymysql/connections.py", line 1075, in read
    first_packet = self.connection._read_packet()
  File "/root/.virtualenvs/python1811/lib/python3.5/site-packages/pymysql/connections.py", line 684, in _read_packet
    packet.check_error()
  File "/root/.virtualenvs/python1811/lib/python3.5/site-packages/pymysql/protocol.py", line 220, in check_error
    err.raise_mysql_exception(self._data)
  File "/root/.virtualenvs/python1811/lib/python3.5/site-packages/pymysql/err.py", line 109, in raise_mysql_exception
    raise errorclass(errno, errval)
pymysql.err.ProgrammingError: (1146, "Table 'szpython1811axf.axf_order' doesn't exist")

The above exception was the direct cause of the following exception:

Traceback (most recent call last):
  File "/root/.virtualenvs/python1811/lib/python3.5/site-packages/django/core/handlers/exception.py", line 41, in inner
    response = get_response(request)
  File "/root/.virtualenvs/python1811/lib/python3.5/site-packages/django/core/handlers/base.py", line 187, in _get_response
    response = self.process_exception_by_middleware(e, request)
  File "/root/.virtualenvs/python1811/lib/python3.5/site-packages/django/core/handlers/base.py", line 185, in _get_response
    response = wrapped_callback(request, *callback_args, **callback_kwargs)
  File "./app/views.py", line 313, in generateorder
    order.save()
  File "/root/.virtualenvs/python1811/lib/python3.5/site-packages/django/db/models/base.py", line 807, in save
    force_update=force_update, update_fields=update_fields)
  File "/root/.virtualenvs/python1811/lib/python3.5/site-packages/django/db/models/base.py", line 837, in save_base
    updated = self._save_table(raw, cls, force_insert, force_update, using, update_fields)
  File "/root/.virtualenvs/python1811/lib/python3.5/site-packages/django/db/models/base.py", line 923, in _save_table
    result = self._do_insert(cls._base_manager, using, fields, update_pk, raw)
  File "/root/.virtualenvs/python1811/lib/python3.5/site-packages/django/db/models/base.py", line 962, in _do_insert
    using=using, raw=raw)
  File "/root/.virtualenvs/python1811/lib/python3.5/site-packages/django/db/models/manager.py", line 85, in manager_method
    return getattr(self.get_queryset(), name)(*args, **kwargs)
  File "/root/.virtualenvs/python1811/lib/python3.5/site-packages/django/db/models/query.py", line 1076, in _insert
    return query.get_compiler(using=using).execute_sql(return_id)
  File "/root/.virtualenvs/python1811/lib/python3.5/site-packages/django/db/models/sql/compiler.py", line 1107, in execute_sql
    cursor.execute(sql, params)
  File "/root/.virtualenvs/python1811/lib/python3.5/site-packages/django/db/backends/utils.py", line 80, in execute
    return super(CursorDebugWrapper, self).execute(sql, params)
  File "/root/.virtualenvs/python1811/lib/python3.5/site-packages/django/db/backends/utils.py", line 65, in execute
    return self.cursor.execute(sql, params)
  File "/root/.virtualenvs/python1811/lib/python3.5/site-packages/django/db/utils.py", line 94, in __exit__
    six.reraise(dj_exc_type, dj_exc_value, traceback)
  File "/root/.virtualenvs/python1811/lib/python3.5/site-packages/django/utils/six.py", line 685, in reraise
    raise value.with_traceback(tb)
  File "/root/.virtualenvs/python1811/lib/python3.5/site-packages/django/db/backends/utils.py", line 65, in execute
    return self.cursor.execute(sql, params)
  File "/root/.virtualenvs/python1811/lib/python3.5/site-packages/django/db/backends/mysql/base.py", line 101, in execute
    return self.cursor.execute(query, args)
  File "/root/.virtualenvs/python1811/lib/python3.5/site-packages/pymysql/cursors.py", line 170, in execute
    result = self._query(query)
  File "/root/.virtualenvs/python1811/lib/python3.5/site-packages/pymysql/cursors.py", line 328, in _query
    conn.query(q)
  File "/root/.virtualenvs/python1811/lib/python3.5/site-packages/pymysql/connections.py", line 517, in query
    self._affected_rows = self._read_query_result(unbuffered=unbuffered)
  File "/root/.virtualenvs/python1811/lib/python3.5/site-packages/pymysql/connections.py", line 732, in _read_query_result
    result.read()
  File "/root/.virtualenvs/python1811/lib/python3.5/site-packages/pymysql/connections.py", line 1075, in read
    first_packet = self.connection._read_packet()
  File "/root/.virtualenvs/python1811/lib/python3.5/site-packages/pymysql/connections.py", line 684, in _read_packet
    packet.check_error()
  File "/root/.virtualenvs/python1811/lib/python3.5/site-packages/pymysql/protocol.py", line 220, in check_error
    err.raise_mysql_exception(self._data)
  File "/root/.virtualenvs/python1811/lib/python3.5/site-packages/pymysql/err.py", line 109, in raise_mysql_exception
    raise errorclass(errno, errval)
django.db.utils.ProgrammingError: (1146, "Table 'szpython1811axf.axf_order' doesn't exist")
[pid: 22031|app: 0|req: 6/6] 113.87.161.170 () {44 vars in 762 bytes} [Fri Jan 18 07:01:43 2019] GET /axf/generateorder/ => generated 17337 bytes in 95 msecs (HTTP/1.1 500) 4 headers in 130 bytes (1 switches on core 0)
Internal Server Error: /axf/generateorder/
Traceback (most recent call last):
  File "/root/.virtualenvs/python1811/lib/python3.5/site-packages/django/db/backends/utils.py", line 65, in execute
    return self.cursor.execute(sql, params)
  File "/root/.virtualenvs/python1811/lib/python3.5/site-packages/django/db/backends/mysql/base.py", line 101, in execute
    return self.cursor.execute(query, args)
  File "/root/.virtualenvs/python1811/lib/python3.5/site-packages/pymysql/cursors.py", line 170, in execute
    result = self._query(query)
  File "/root/.virtualenvs/python1811/lib/python3.5/site-packages/pymysql/cursors.py", line 328, in _query
    conn.query(q)
  File "/root/.virtualenvs/python1811/lib/python3.5/site-packages/pymysql/connections.py", line 517, in query
    self._affected_rows = self._read_query_result(unbuffered=unbuffered)
  File "/root/.virtualenvs/python1811/lib/python3.5/site-packages/pymysql/connections.py", line 732, in _read_query_result
    result.read()
  File "/root/.virtualenvs/python1811/lib/python3.5/site-packages/pymysql/connections.py", line 1075, in read
    first_packet = self.connection._read_packet()
  File "/root/.virtualenvs/python1811/lib/python3.5/site-packages/pymysql/connections.py", line 684, in _read_packet
    packet.check_error()
  File "/root/.virtualenvs/python1811/lib/python3.5/site-packages/pymysql/protocol.py", line 220, in check_error
    err.raise_mysql_exception(self._data)
  File "/root/.virtualenvs/python1811/lib/python3.5/site-packages/pymysql/err.py", line 109, in raise_mysql_exception
    raise errorclass(errno, errval)
pymysql.err.ProgrammingError: (1146, "Table 'szpython1811axf.axf_order' doesn't exist")

The above exception was the direct cause of the following exception:

Traceback (most recent call last):
  File "/root/.virtualenvs/python1811/lib/python3.5/site-packages/django/core/handlers/exception.py", line 41, in inner
    response = get_response(request)
  File "/root/.virtualenvs/python1811/lib/python3.5/site-packages/django/core/handlers/base.py", line 187, in _get_response
    response = self.process_exception_by_middleware(e, request)
  File "/root/.virtualenvs/python1811/lib/python3.5/site-packages/django/core/handlers/base.py", line 185, in _get_response
    response = wrapped_callback(request, *callback_args, **callback_kwargs)
  File "./app/views.py", line 313, in generateorder
    order.save()
  File "/root/.virtualenvs/python1811/lib/python3.5/site-packages/django/db/models/base.py", line 807, in save
    force_update=force_update, update_fields=update_fields)
  File "/root/.virtualenvs/python1811/lib/python3.5/site-packages/django/db/models/base.py", line 837, in save_base
    updated = self._save_table(raw, cls, force_insert, force_update, using, update_fields)
  File "/root/.virtualenvs/python1811/lib/python3.5/site-packages/django/db/models/base.py", line 923, in _save_table
    result = self._do_insert(cls._base_manager, using, fields, update_pk, raw)
  File "/root/.virtualenvs/python1811/lib/python3.5/site-packages/django/db/models/base.py", line 962, in _do_insert
    using=using, raw=raw)
  File "/root/.virtualenvs/python1811/lib/python3.5/site-packages/django/db/models/manager.py", line 85, in manager_method
    return getattr(self.get_queryset(), name)(*args, **kwargs)
  File "/root/.virtualenvs/python1811/lib/python3.5/site-packages/django/db/models/query.py", line 1076, in _insert
    return query.get_compiler(using=using).execute_sql(return_id)
  File "/root/.virtualenvs/python1811/lib/python3.5/site-packages/django/db/models/sql/compiler.py", line 1107, in execute_sql
    cursor.execute(sql, params)
  File "/root/.virtualenvs/python1811/lib/python3.5/site-packages/django/db/backends/utils.py", line 80, in execute
    return super(CursorDebugWrapper, self).execute(sql, params)
  File "/root/.virtualenvs/python1811/lib/python3.5/site-packages/django/db/backends/utils.py", line 65, in execute
    return self.cursor.execute(sql, params)
  File "/root/.virtualenvs/python1811/lib/python3.5/site-packages/django/db/utils.py", line 94, in __exit__
    six.reraise(dj_exc_type, dj_exc_value, traceback)
  File "/root/.virtualenvs/python1811/lib/python3.5/site-packages/django/utils/six.py", line 685, in reraise
    raise value.with_traceback(tb)
  File "/root/.virtualenvs/python1811/lib/python3.5/site-packages/django/db/backends/utils.py", line 65, in execute
    return self.cursor.execute(sql, params)
  File "/root/.virtualenvs/python1811/lib/python3.5/site-packages/django/db/backends/mysql/base.py", line 101, in execute
    return self.cursor.execute(query, args)
  File "/root/.virtualenvs/python1811/lib/python3.5/site-packages/pymysql/cursors.py", line 170, in execute
    result = self._query(query)
  File "/root/.virtualenvs/python1811/lib/python3.5/site-packages/pymysql/cursors.py", line 328, in _query
    conn.query(q)
  File "/root/.virtualenvs/python1811/lib/python3.5/site-packages/pymysql/connections.py", line 517, in query
    self._affected_rows = self._read_query_result(unbuffered=unbuffered)
  File "/root/.virtualenvs/python1811/lib/python3.5/site-packages/pymysql/connections.py", line 732, in _read_query_result
    result.read()
  File "/root/.virtualenvs/python1811/lib/python3.5/site-packages/pymysql/connections.py", line 1075, in read
    first_packet = self.connection._read_packet()
  File "/root/.virtualenvs/python1811/lib/python3.5/site-packages/pymysql/connections.py", line 684, in _read_packet
    packet.check_error()
  File "/root/.virtualenvs/python1811/lib/python3.5/site-packages/pymysql/protocol.py", line 220, in check_error
    err.raise_mysql_exception(self._data)
  File "/root/.virtualenvs/python1811/lib/python3.5/site-packages/pymysql/err.py", line 109, in raise_mysql_exception
    raise errorclass(errno, errval)
django.db.utils.ProgrammingError: (1146, "Table 'szpython1811axf.axf_order' doesn't exist")
[pid: 22031|app: 0|req: 7/7] 113.87.161.170 () {44 vars in 762 bytes} [Fri Jan 18 07:01:46 2019] GET /axf/generateorder/ => generated 17337 bytes in 39 msecs (HTTP/1.1 500) 4 headers in 130 bytes (1 switches on core 0)
[pid: 22031|app: 0|req: 8/8] 113.87.161.170 () {42 vars in 756 bytes} [Fri Jan 18 07:01:57 2019] GET /axf/cart/ => generated 7037 bytes in 27 msecs (HTTP/1.1 200) 4 headers in 124 bytes (1 switches on core 0)
Internal Server Error: /axf/generateorder/
Traceback (most recent call last):
  File "/root/.virtualenvs/python1811/lib/python3.5/site-packages/django/db/backends/utils.py", line 65, in execute
    return self.cursor.execute(sql, params)
  File "/root/.virtualenvs/python1811/lib/python3.5/site-packages/django/db/backends/mysql/base.py", line 101, in execute
    return self.cursor.execute(query, args)
  File "/root/.virtualenvs/python1811/lib/python3.5/site-packages/pymysql/cursors.py", line 170, in execute
    result = self._query(query)
  File "/root/.virtualenvs/python1811/lib/python3.5/site-packages/pymysql/cursors.py", line 328, in _query
    conn.query(q)
  File "/root/.virtualenvs/python1811/lib/python3.5/site-packages/pymysql/connections.py", line 517, in query
    self._affected_rows = self._read_query_result(unbuffered=unbuffered)
  File "/root/.virtualenvs/python1811/lib/python3.5/site-packages/pymysql/connections.py", line 732, in _read_query_result
    result.read()
  File "/root/.virtualenvs/python1811/lib/python3.5/site-packages/pymysql/connections.py", line 1075, in read
    first_packet = self.connection._read_packet()
  File "/root/.virtualenvs/python1811/lib/python3.5/site-packages/pymysql/connections.py", line 684, in _read_packet
    packet.check_error()
  File "/root/.virtualenvs/python1811/lib/python3.5/site-packages/pymysql/protocol.py", line 220, in check_error
    err.raise_mysql_exception(self._data)
  File "/root/.virtualenvs/python1811/lib/python3.5/site-packages/pymysql/err.py", line 109, in raise_mysql_exception
    raise errorclass(errno, errval)
pymysql.err.ProgrammingError: (1146, "Table 'szpython1811axf.axf_order' doesn't exist")

The above exception was the direct cause of the following exception:

Traceback (most recent call last):
  File "/root/.virtualenvs/python1811/lib/python3.5/site-packages/django/core/handlers/exception.py", line 41, in inner
    response = get_response(request)
  File "/root/.virtualenvs/python1811/lib/python3.5/site-packages/django/core/handlers/base.py", line 187, in _get_response
    response = self.process_exception_by_middleware(e, request)
  File "/root/.virtualenvs/python1811/lib/python3.5/site-packages/django/core/handlers/base.py", line 185, in _get_response
    response = wrapped_callback(request, *callback_args, **callback_kwargs)
  File "./app/views.py", line 313, in generateorder
    order.save()
  File "/root/.virtualenvs/python1811/lib/python3.5/site-packages/django/db/models/base.py", line 807, in save
    force_update=force_update, update_fields=update_fields)
  File "/root/.virtualenvs/python1811/lib/python3.5/site-packages/django/db/models/base.py", line 837, in save_base
    updated = self._save_table(raw, cls, force_insert, force_update, using, update_fields)
  File "/root/.virtualenvs/python1811/lib/python3.5/site-packages/django/db/models/base.py", line 923, in _save_table
    result = self._do_insert(cls._base_manager, using, fields, update_pk, raw)
  File "/root/.virtualenvs/python1811/lib/python3.5/site-packages/django/db/models/base.py", line 962, in _do_insert
    using=using, raw=raw)
  File "/root/.virtualenvs/python1811/lib/python3.5/site-packages/django/db/models/manager.py", line 85, in manager_method
    return getattr(self.get_queryset(), name)(*args, **kwargs)
  File "/root/.virtualenvs/python1811/lib/python3.5/site-packages/django/db/models/query.py", line 1076, in _insert
    return query.get_compiler(using=using).execute_sql(return_id)
  File "/root/.virtualenvs/python1811/lib/python3.5/site-packages/django/db/models/sql/compiler.py", line 1107, in execute_sql
    cursor.execute(sql, params)
  File "/root/.virtualenvs/python1811/lib/python3.5/site-packages/django/db/backends/utils.py", line 80, in execute
    return super(CursorDebugWrapper, self).execute(sql, params)
  File "/root/.virtualenvs/python1811/lib/python3.5/site-packages/django/db/backends/utils.py", line 65, in execute
    return self.cursor.execute(sql, params)
  File "/root/.virtualenvs/python1811/lib/python3.5/site-packages/django/db/utils.py", line 94, in __exit__
    six.reraise(dj_exc_type, dj_exc_value, traceback)
  File "/root/.virtualenvs/python1811/lib/python3.5/site-packages/django/utils/six.py", line 685, in reraise
    raise value.with_traceback(tb)
  File "/root/.virtualenvs/python1811/lib/python3.5/site-packages/django/db/backends/utils.py", line 65, in execute
    return self.cursor.execute(sql, params)
  File "/root/.virtualenvs/python1811/lib/python3.5/site-packages/django/db/backends/mysql/base.py", line 101, in execute
    return self.cursor.execute(query, args)
  File "/root/.virtualenvs/python1811/lib/python3.5/site-packages/pymysql/cursors.py", line 170, in execute
    result = self._query(query)
  File "/root/.virtualenvs/python1811/lib/python3.5/site-packages/pymysql/cursors.py", line 328, in _query
    conn.query(q)
  File "/root/.virtualenvs/python1811/lib/python3.5/site-packages/pymysql/connections.py", line 517, in query
    self._affected_rows = self._read_query_result(unbuffered=unbuffered)
  File "/root/.virtualenvs/python1811/lib/python3.5/site-packages/pymysql/connections.py", line 732, in _read_query_result
    result.read()
  File "/root/.virtualenvs/python1811/lib/python3.5/site-packages/pymysql/connections.py", line 1075, in read
    first_packet = self.connection._read_packet()
  File "/root/.virtualenvs/python1811/lib/python3.5/site-packages/pymysql/connections.py", line 684, in _read_packet
    packet.check_error()
  File "/root/.virtualenvs/python1811/lib/python3.5/site-packages/pymysql/protocol.py", line 220, in check_error
    err.raise_mysql_exception(self._data)
  File "/root/.virtualenvs/python1811/lib/python3.5/site-packages/pymysql/err.py", line 109, in raise_mysql_exception
    raise errorclass(errno, errval)
django.db.utils.ProgrammingError: (1146, "Table 'szpython1811axf.axf_order' doesn't exist")
[pid: 22031|app: 0|req: 9/9] 113.87.161.170 () {44 vars in 762 bytes} [Fri Jan 18 07:02:00 2019] GET /axf/generateorder/ => generated 17337 bytes in 35 msecs (HTTP/1.1 500) 4 headers in 130 bytes (1 switches on core 0)
Internal Server Error: /axf/generateorder/
Traceback (most recent call last):
  File "/root/.virtualenvs/python1811/lib/python3.5/site-packages/django/db/backends/utils.py", line 65, in execute
    return self.cursor.execute(sql, params)
  File "/root/.virtualenvs/python1811/lib/python3.5/site-packages/django/db/backends/mysql/base.py", line 101, in execute
    return self.cursor.execute(query, args)
  File "/root/.virtualenvs/python1811/lib/python3.5/site-packages/pymysql/cursors.py", line 170, in execute
    result = self._query(query)
  File "/root/.virtualenvs/python1811/lib/python3.5/site-packages/pymysql/cursors.py", line 328, in _query
    conn.query(q)
  File "/root/.virtualenvs/python1811/lib/python3.5/site-packages/pymysql/connections.py", line 517, in query
    self._affected_rows = self._read_query_result(unbuffered=unbuffered)
  File "/root/.virtualenvs/python1811/lib/python3.5/site-packages/pymysql/connections.py", line 732, in _read_query_result
    result.read()
  File "/root/.virtualenvs/python1811/lib/python3.5/site-packages/pymysql/connections.py", line 1075, in read
    first_packet = self.connection._read_packet()
  File "/root/.virtualenvs/python1811/lib/python3.5/site-packages/pymysql/connections.py", line 684, in _read_packet
    packet.check_error()
  File "/root/.virtualenvs/python1811/lib/python3.5/site-packages/pymysql/protocol.py", line 220, in check_error
    err.raise_mysql_exception(self._data)
  File "/root/.virtualenvs/python1811/lib/python3.5/site-packages/pymysql/err.py", line 109, in raise_mysql_exception
    raise errorclass(errno, errval)
pymysql.err.ProgrammingError: (1146, "Table 'szpython1811axf.axf_order' doesn't exist")

The above exception was the direct cause of the following exception:

Traceback (most recent call last):
  File "/root/.virtualenvs/python1811/lib/python3.5/site-packages/django/core/handlers/exception.py", line 41, in inner
    response = get_response(request)
  File "/root/.virtualenvs/python1811/lib/python3.5/site-packages/django/core/handlers/base.py", line 187, in _get_response
    response = self.process_exception_by_middleware(e, request)
  File "/root/.virtualenvs/python1811/lib/python3.5/site-packages/django/core/handlers/base.py", line 185, in _get_response
    response = wrapped_callback(request, *callback_args, **callback_kwargs)
  File "./app/views.py", line 313, in generateorder
    order.save()
  File "/root/.virtualenvs/python1811/lib/python3.5/site-packages/django/db/models/base.py", line 807, in save
    force_update=force_update, update_fields=update_fields)
  File "/root/.virtualenvs/python1811/lib/python3.5/site-packages/django/db/models/base.py", line 837, in save_base
    updated = self._save_table(raw, cls, force_insert, force_update, using, update_fields)
  File "/root/.virtualenvs/python1811/lib/python3.5/site-packages/django/db/models/base.py", line 923, in _save_table
    result = self._do_insert(cls._base_manager, using, fields, update_pk, raw)
  File "/root/.virtualenvs/python1811/lib/python3.5/site-packages/django/db/models/base.py", line 962, in _do_insert
    using=using, raw=raw)
  File "/root/.virtualenvs/python1811/lib/python3.5/site-packages/django/db/models/manager.py", line 85, in manager_method
    return getattr(self.get_queryset(), name)(*args, **kwargs)
  File "/root/.virtualenvs/python1811/lib/python3.5/site-packages/django/db/models/query.py", line 1076, in _insert
    return query.get_compiler(using=using).execute_sql(return_id)
  File "/root/.virtualenvs/python1811/lib/python3.5/site-packages/django/db/models/sql/compiler.py", line 1107, in execute_sql
    cursor.execute(sql, params)
  File "/root/.virtualenvs/python1811/lib/python3.5/site-packages/django/db/backends/utils.py", line 80, in execute
    return super(CursorDebugWrapper, self).execute(sql, params)
  File "/root/.virtualenvs/python1811/lib/python3.5/site-packages/django/db/backends/utils.py", line 65, in execute
    return self.cursor.execute(sql, params)
  File "/root/.virtualenvs/python1811/lib/python3.5/site-packages/django/db/utils.py", line 94, in __exit__
    six.reraise(dj_exc_type, dj_exc_value, traceback)
  File "/root/.virtualenvs/python1811/lib/python3.5/site-packages/django/utils/six.py", line 685, in reraise
    raise value.with_traceback(tb)
  File "/root/.virtualenvs/python1811/lib/python3.5/site-packages/django/db/backends/utils.py", line 65, in execute
    return self.cursor.execute(sql, params)
  File "/root/.virtualenvs/python1811/lib/python3.5/site-packages/django/db/backends/mysql/base.py", line 101, in execute
    return self.cursor.execute(query, args)
  File "/root/.virtualenvs/python1811/lib/python3.5/site-packages/pymysql/cursors.py", line 170, in execute
    result = self._query(query)
  File "/root/.virtualenvs/python1811/lib/python3.5/site-packages/pymysql/cursors.py", line 328, in _query
    conn.query(q)
  File "/root/.virtualenvs/python1811/lib/python3.5/site-packages/pymysql/connections.py", line 517, in query
    self._affected_rows = self._read_query_result(unbuffered=unbuffered)
  File "/root/.virtualenvs/python1811/lib/python3.5/site-packages/pymysql/connections.py", line 732, in _read_query_result
    result.read()
  File "/root/.virtualenvs/python1811/lib/python3.5/site-packages/pymysql/connections.py", line 1075, in read
    first_packet = self.connection._read_packet()
  File "/root/.virtualenvs/python1811/lib/python3.5/site-packages/pymysql/connections.py", line 684, in _read_packet
    packet.check_error()
  File "/root/.virtualenvs/python1811/lib/python3.5/site-packages/pymysql/protocol.py", line 220, in check_error
    err.raise_mysql_exception(self._data)
  File "/root/.virtualenvs/python1811/lib/python3.5/site-packages/pymysql/err.py", line 109, in raise_mysql_exception
    raise errorclass(errno, errval)
django.db.utils.ProgrammingError: (1146, "Table 'szpython1811axf.axf_order' doesn't exist")
[pid: 22031|app: 0|req: 10/10] 113.87.161.170 () {44 vars in 762 bytes} [Fri Jan 18 07:02:06 2019] GET /axf/generateorder/ => generated 17337 bytes in 35 msecs (HTTP/1.1 500) 4 headers in 130 bytes (1 switches on core 0)
Internal Server Error: /axf/generateorder/
Traceback (most recent call last):
  File "/root/.virtualenvs/python1811/lib/python3.5/site-packages/django/db/backends/utils.py", line 65, in execute
    return self.cursor.execute(sql, params)
  File "/root/.virtualenvs/python1811/lib/python3.5/site-packages/django/db/backends/mysql/base.py", line 101, in execute
    return self.cursor.execute(query, args)
  File "/root/.virtualenvs/python1811/lib/python3.5/site-packages/pymysql/cursors.py", line 170, in execute
    result = self._query(query)
  File "/root/.virtualenvs/python1811/lib/python3.5/site-packages/pymysql/cursors.py", line 328, in _query
    conn.query(q)
  File "/root/.virtualenvs/python1811/lib/python3.5/site-packages/pymysql/connections.py", line 517, in query
    self._affected_rows = self._read_query_result(unbuffered=unbuffered)
  File "/root/.virtualenvs/python1811/lib/python3.5/site-packages/pymysql/connections.py", line 732, in _read_query_result
    result.read()
  File "/root/.virtualenvs/python1811/lib/python3.5/site-packages/pymysql/connections.py", line 1075, in read
    first_packet = self.connection._read_packet()
  File "/root/.virtualenvs/python1811/lib/python3.5/site-packages/pymysql/connections.py", line 684, in _read_packet
    packet.check_error()
  File "/root/.virtualenvs/python1811/lib/python3.5/site-packages/pymysql/protocol.py", line 220, in check_error
    err.raise_mysql_exception(self._data)
  File "/root/.virtualenvs/python1811/lib/python3.5/site-packages/pymysql/err.py", line 109, in raise_mysql_exception
    raise errorclass(errno, errval)
pymysql.err.ProgrammingError: (1146, "Table 'szpython1811axf.axf_order' doesn't exist")

The above exception was the direct cause of the following exception:

Traceback (most recent call last):
  File "/root/.virtualenvs/python1811/lib/python3.5/site-packages/django/core/handlers/exception.py", line 41, in inner
    response = get_response(request)
  File "/root/.virtualenvs/python1811/lib/python3.5/site-packages/django/core/handlers/base.py", line 187, in _get_response
    response = self.process_exception_by_middleware(e, request)
  File "/root/.virtualenvs/python1811/lib/python3.5/site-packages/django/core/handlers/base.py", line 185, in _get_response
    response = wrapped_callback(request, *callback_args, **callback_kwargs)
  File "./app/views.py", line 313, in generateorder
    order.save()
  File "/root/.virtualenvs/python1811/lib/python3.5/site-packages/django/db/models/base.py", line 807, in save
    force_update=force_update, update_fields=update_fields)
  File "/root/.virtualenvs/python1811/lib/python3.5/site-packages/django/db/models/base.py", line 837, in save_base
    updated = self._save_table(raw, cls, force_insert, force_update, using, update_fields)
  File "/root/.virtualenvs/python1811/lib/python3.5/site-packages/django/db/models/base.py", line 923, in _save_table
    result = self._do_insert(cls._base_manager, using, fields, update_pk, raw)
  File "/root/.virtualenvs/python1811/lib/python3.5/site-packages/django/db/models/base.py", line 962, in _do_insert
    using=using, raw=raw)
  File "/root/.virtualenvs/python1811/lib/python3.5/site-packages/django/db/models/manager.py", line 85, in manager_method
    return getattr(self.get_queryset(), name)(*args, **kwargs)
  File "/root/.virtualenvs/python1811/lib/python3.5/site-packages/django/db/models/query.py", line 1076, in _insert
    return query.get_compiler(using=using).execute_sql(return_id)
  File "/root/.virtualenvs/python1811/lib/python3.5/site-packages/django/db/models/sql/compiler.py", line 1107, in execute_sql
    cursor.execute(sql, params)
  File "/root/.virtualenvs/python1811/lib/python3.5/site-packages/django/db/backends/utils.py", line 80, in execute
    return super(CursorDebugWrapper, self).execute(sql, params)
  File "/root/.virtualenvs/python1811/lib/python3.5/site-packages/django/db/backends/utils.py", line 65, in execute
    return self.cursor.execute(sql, params)
  File "/root/.virtualenvs/python1811/lib/python3.5/site-packages/django/db/utils.py", line 94, in __exit__
    six.reraise(dj_exc_type, dj_exc_value, traceback)
  File "/root/.virtualenvs/python1811/lib/python3.5/site-packages/django/utils/six.py", line 685, in reraise
    raise value.with_traceback(tb)
  File "/root/.virtualenvs/python1811/lib/python3.5/site-packages/django/db/backends/utils.py", line 65, in execute
    return self.cursor.execute(sql, params)
  File "/root/.virtualenvs/python1811/lib/python3.5/site-packages/django/db/backends/mysql/base.py", line 101, in execute
    return self.cursor.execute(query, args)
  File "/root/.virtualenvs/python1811/lib/python3.5/site-packages/pymysql/cursors.py", line 170, in execute
    result = self._query(query)
  File "/root/.virtualenvs/python1811/lib/python3.5/site-packages/pymysql/cursors.py", line 328, in _query
    conn.query(q)
  File "/root/.virtualenvs/python1811/lib/python3.5/site-packages/pymysql/connections.py", line 517, in query
    self._affected_rows = self._read_query_result(unbuffered=unbuffered)
  File "/root/.virtualenvs/python1811/lib/python3.5/site-packages/pymysql/connections.py", line 732, in _read_query_result
    result.read()
  File "/root/.virtualenvs/python1811/lib/python3.5/site-packages/pymysql/connections.py", line 1075, in read
    first_packet = self.connection._read_packet()
  File "/root/.virtualenvs/python1811/lib/python3.5/site-packages/pymysql/connections.py", line 684, in _read_packet
    packet.check_error()
  File "/root/.virtualenvs/python1811/lib/python3.5/site-packages/pymysql/protocol.py", line 220, in check_error
    err.raise_mysql_exception(self._data)
  File "/root/.virtualenvs/python1811/lib/python3.5/site-packages/pymysql/err.py", line 109, in raise_mysql_exception
    raise errorclass(errno, errval)
django.db.utils.ProgrammingError: (1146, "Table 'szpython1811axf.axf_order' doesn't exist")
[pid: 22031|app: 0|req: 11/11] 113.87.161.170 () {44 vars in 762 bytes} [Fri Jan 18 07:02:07 2019] GET /axf/generateorder/ => generated 17337 bytes in 33 msecs (HTTP/1.1 500) 4 headers in 130 bytes (1 switches on core 0)
Forbidden (CSRF cookie not set.): /axf/appnotify/
[pid: 22031|app: 0|req: 12/12] 140.205.118.152 () {34 vars in 500 bytes} [Fri Jan 18 07:05:47 2019] POST /axf/appnotify/ => generated 2857 bytes in 48 msecs (HTTP/1.1 403) 3 headers in 102 bytes (1 switches on core 0)
[pid: 22031|app: 0|req: 13/13] 113.87.160.245 () {42 vars in 2099 bytes} [Fri Jan 18 07:05:58 2019] GET /axf/returnview/?charset=utf-8&out_trade_no=15477950570.8758113284775508&method=alipay.trade.page.pay.return&total_amount=19.80&sign=WTXKsOMB3ooWcfo18LVtPO2vRkB3Z8sb8at2PlCaZXdchhpZS8emVjae%2B3TFHOOcbaHKhtcVVex4Sji%2B62FQCmVH1FMzDeQ1N4mLW9VsDbiH4KPYCSkZvOE4oSNliyBOvAWPeXB6t3FrM0pPgV8WOpSXaHpo4ms9xRVZx5kKdzuM%2B5QVJatzyFqEP0JFYB%2FPMPB5hrxN3I4KHvnFCiJT4fGzpWJm%2BDIXgC%2FOMUcZjtbQLymD6b5qJPsy7qohjzLHZuYV4QrDteT6gn%2BPgaFQgfndB8%2Fe1l7RRDQoUf79NKSll4Fck1UQ2r%2BeewHY8sRsKmn%2BY6I9p%2FzwlCTPbQlcfQ%3D%3D&trade_no=2019011822001416700501216860&auth_app_id=2016091800542542&version=1.0&app_id=2016091800542542&sign_type=RSA2&seller_id=2088102176233911&timestamp=2019-01-18+15%3A05%3A54 => generated 0 bytes in 1 msecs (HTTP/1.1 302) 4 headers in 132 bytes (1 switches on core 0)
[pid: 22031|app: 0|req: 14/14] 113.87.160.245 () {42 vars in 756 bytes} [Fri Jan 18 07:05:58 2019] GET /axf/mine/ => generated 5847 bytes in 11 msecs (HTTP/1.1 200) 4 headers in 124 bytes (1 switches on core 0)
[pid: 22031|app: 0|req: 15/15] 113.87.160.245 () {44 vars in 800 bytes} [Fri Jan 18 07:06:36 2019] GET /axf/cart/ => generated 7037 bytes in 22 msecs (HTTP/1.1 200) 4 headers in 124 bytes (1 switches on core 0)
[pid: 22031|app: 0|req: 16/16] 113.87.160.245 () {44 vars in 785 bytes} [Fri Jan 18 07:06:41 2019] GET /axf/changecartstatus/?cartid=3 => generated 79 bytes in 8 msecs (HTTP/1.1 200) 3 headers in 100 bytes (1 switches on core 0)
Internal Server Error: /axf/generateorder/
Traceback (most recent call last):
  File "/root/.virtualenvs/python1811/lib/python3.5/site-packages/django/db/backends/utils.py", line 65, in execute
    return self.cursor.execute(sql, params)
  File "/root/.virtualenvs/python1811/lib/python3.5/site-packages/django/db/backends/mysql/base.py", line 101, in execute
    return self.cursor.execute(query, args)
  File "/root/.virtualenvs/python1811/lib/python3.5/site-packages/pymysql/cursors.py", line 170, in execute
    result = self._query(query)
  File "/root/.virtualenvs/python1811/lib/python3.5/site-packages/pymysql/cursors.py", line 328, in _query
    conn.query(q)
  File "/root/.virtualenvs/python1811/lib/python3.5/site-packages/pymysql/connections.py", line 517, in query
    self._affected_rows = self._read_query_result(unbuffered=unbuffered)
  File "/root/.virtualenvs/python1811/lib/python3.5/site-packages/pymysql/connections.py", line 732, in _read_query_result
    result.read()
  File "/root/.virtualenvs/python1811/lib/python3.5/site-packages/pymysql/connections.py", line 1075, in read
    first_packet = self.connection._read_packet()
  File "/root/.virtualenvs/python1811/lib/python3.5/site-packages/pymysql/connections.py", line 684, in _read_packet
    packet.check_error()
  File "/root/.virtualenvs/python1811/lib/python3.5/site-packages/pymysql/protocol.py", line 220, in check_error
    err.raise_mysql_exception(self._data)
  File "/root/.virtualenvs/python1811/lib/python3.5/site-packages/pymysql/err.py", line 109, in raise_mysql_exception
    raise errorclass(errno, errval)
pymysql.err.ProgrammingError: (1146, "Table 'szpython1811axf.axf_order' doesn't exist")

The above exception was the direct cause of the following exception:

Traceback (most recent call last):
  File "/root/.virtualenvs/python1811/lib/python3.5/site-packages/django/core/handlers/exception.py", line 41, in inner
    response = get_response(request)
  File "/root/.virtualenvs/python1811/lib/python3.5/site-packages/django/core/handlers/base.py", line 187, in _get_response
    response = self.process_exception_by_middleware(e, request)
  File "/root/.virtualenvs/python1811/lib/python3.5/site-packages/django/core/handlers/base.py", line 185, in _get_response
    response = wrapped_callback(request, *callback_args, **callback_kwargs)
  File "./app/views.py", line 313, in generateorder
    order.save()
  File "/root/.virtualenvs/python1811/lib/python3.5/site-packages/django/db/models/base.py", line 807, in save
    force_update=force_update, update_fields=update_fields)
  File "/root/.virtualenvs/python1811/lib/python3.5/site-packages/django/db/models/base.py", line 837, in save_base
    updated = self._save_table(raw, cls, force_insert, force_update, using, update_fields)
  File "/root/.virtualenvs/python1811/lib/python3.5/site-packages/django/db/models/base.py", line 923, in _save_table
    result = self._do_insert(cls._base_manager, using, fields, update_pk, raw)
  File "/root/.virtualenvs/python1811/lib/python3.5/site-packages/django/db/models/base.py", line 962, in _do_insert
    using=using, raw=raw)
  File "/root/.virtualenvs/python1811/lib/python3.5/site-packages/django/db/models/manager.py", line 85, in manager_method
    return getattr(self.get_queryset(), name)(*args, **kwargs)
  File "/root/.virtualenvs/python1811/lib/python3.5/site-packages/django/db/models/query.py", line 1076, in _insert
    return query.get_compiler(using=using).execute_sql(return_id)
  File "/root/.virtualenvs/python1811/lib/python3.5/site-packages/django/db/models/sql/compiler.py", line 1107, in execute_sql
    cursor.execute(sql, params)
  File "/root/.virtualenvs/python1811/lib/python3.5/site-packages/django/db/backends/utils.py", line 80, in execute
    return super(CursorDebugWrapper, self).execute(sql, params)
  File "/root/.virtualenvs/python1811/lib/python3.5/site-packages/django/db/backends/utils.py", line 65, in execute
    return self.cursor.execute(sql, params)
  File "/root/.virtualenvs/python1811/lib/python3.5/site-packages/django/db/utils.py", line 94, in __exit__
    six.reraise(dj_exc_type, dj_exc_value, traceback)
  File "/root/.virtualenvs/python1811/lib/python3.5/site-packages/django/utils/six.py", line 685, in reraise
    raise value.with_traceback(tb)
  File "/root/.virtualenvs/python1811/lib/python3.5/site-packages/django/db/backends/utils.py", line 65, in execute
    return self.cursor.execute(sql, params)
  File "/root/.virtualenvs/python1811/lib/python3.5/site-packages/django/db/backends/mysql/base.py", line 101, in execute
    return self.cursor.execute(query, args)
  File "/root/.virtualenvs/python1811/lib/python3.5/site-packages/pymysql/cursors.py", line 170, in execute
    result = self._query(query)
  File "/root/.virtualenvs/python1811/lib/python3.5/site-packages/pymysql/cursors.py", line 328, in _query
    conn.query(q)
  File "/root/.virtualenvs/python1811/lib/python3.5/site-packages/pymysql/connections.py", line 517, in query
    self._affected_rows = self._read_query_result(unbuffered=unbuffered)
  File "/root/.virtualenvs/python1811/lib/python3.5/site-packages/pymysql/connections.py", line 732, in _read_query_result
    result.read()
  File "/root/.virtualenvs/python1811/lib/python3.5/site-packages/pymysql/connections.py", line 1075, in read
    first_packet = self.connection._read_packet()
  File "/root/.virtualenvs/python1811/lib/python3.5/site-packages/pymysql/connections.py", line 684, in _read_packet
    packet.check_error()
  File "/root/.virtualenvs/python1811/lib/python3.5/site-packages/pymysql/protocol.py", line 220, in check_error
    err.raise_mysql_exception(self._data)
  File "/root/.virtualenvs/python1811/lib/python3.5/site-packages/pymysql/err.py", line 109, in raise_mysql_exception
    raise errorclass(errno, errval)
django.db.utils.ProgrammingError: (1146, "Table 'szpython1811axf.axf_order' doesn't exist")
[pid: 22031|app: 0|req: 17/17] 113.87.160.245 () {44 vars in 762 bytes} [Fri Jan 18 07:06:47 2019] GET /axf/generateorder/ => generated 17337 bytes in 35 msecs (HTTP/1.1 500) 4 headers in 130 bytes (1 switches on core 0)
Internal Server Error: /axf/generateorder/
Traceback (most recent call last):
  File "/root/.virtualenvs/python1811/lib/python3.5/site-packages/django/db/backends/utils.py", line 65, in execute
    return self.cursor.execute(sql, params)
  File "/root/.virtualenvs/python1811/lib/python3.5/site-packages/django/db/backends/mysql/base.py", line 101, in execute
    return self.cursor.execute(query, args)
  File "/root/.virtualenvs/python1811/lib/python3.5/site-packages/pymysql/cursors.py", line 170, in execute
    result = self._query(query)
  File "/root/.virtualenvs/python1811/lib/python3.5/site-packages/pymysql/cursors.py", line 328, in _query
    conn.query(q)
  File "/root/.virtualenvs/python1811/lib/python3.5/site-packages/pymysql/connections.py", line 517, in query
    self._affected_rows = self._read_query_result(unbuffered=unbuffered)
  File "/root/.virtualenvs/python1811/lib/python3.5/site-packages/pymysql/connections.py", line 732, in _read_query_result
    result.read()
  File "/root/.virtualenvs/python1811/lib/python3.5/site-packages/pymysql/connections.py", line 1075, in read
    first_packet = self.connection._read_packet()
  File "/root/.virtualenvs/python1811/lib/python3.5/site-packages/pymysql/connections.py", line 684, in _read_packet
    packet.check_error()
  File "/root/.virtualenvs/python1811/lib/python3.5/site-packages/pymysql/protocol.py", line 220, in check_error
    err.raise_mysql_exception(self._data)
  File "/root/.virtualenvs/python1811/lib/python3.5/site-packages/pymysql/err.py", line 109, in raise_mysql_exception
    raise errorclass(errno, errval)
pymysql.err.ProgrammingError: (1146, "Table 'szpython1811axf.axf_order' doesn't exist")

The above exception was the direct cause of the following exception:

Traceback (most recent call last):
  File "/root/.virtualenvs/python1811/lib/python3.5/site-packages/django/core/handlers/exception.py", line 41, in inner
    response = get_response(request)
  File "/root/.virtualenvs/python1811/lib/python3.5/site-packages/django/core/handlers/base.py", line 187, in _get_response
    response = self.process_exception_by_middleware(e, request)
  File "/root/.virtualenvs/python1811/lib/python3.5/site-packages/django/core/handlers/base.py", line 185, in _get_response
    response = wrapped_callback(request, *callback_args, **callback_kwargs)
  File "./app/views.py", line 313, in generateorder
    order.save()
  File "/root/.virtualenvs/python1811/lib/python3.5/site-packages/django/db/models/base.py", line 807, in save
    force_update=force_update, update_fields=update_fields)
  File "/root/.virtualenvs/python1811/lib/python3.5/site-packages/django/db/models/base.py", line 837, in save_base
    updated = self._save_table(raw, cls, force_insert, force_update, using, update_fields)
  File "/root/.virtualenvs/python1811/lib/python3.5/site-packages/django/db/models/base.py", line 923, in _save_table
    result = self._do_insert(cls._base_manager, using, fields, update_pk, raw)
  File "/root/.virtualenvs/python1811/lib/python3.5/site-packages/django/db/models/base.py", line 962, in _do_insert
    using=using, raw=raw)
  File "/root/.virtualenvs/python1811/lib/python3.5/site-packages/django/db/models/manager.py", line 85, in manager_method
    return getattr(self.get_queryset(), name)(*args, **kwargs)
  File "/root/.virtualenvs/python1811/lib/python3.5/site-packages/django/db/models/query.py", line 1076, in _insert
    return query.get_compiler(using=using).execute_sql(return_id)
  File "/root/.virtualenvs/python1811/lib/python3.5/site-packages/django/db/models/sql/compiler.py", line 1107, in execute_sql
    cursor.execute(sql, params)
  File "/root/.virtualenvs/python1811/lib/python3.5/site-packages/django/db/backends/utils.py", line 80, in execute
    return super(CursorDebugWrapper, self).execute(sql, params)
  File "/root/.virtualenvs/python1811/lib/python3.5/site-packages/django/db/backends/utils.py", line 65, in execute
    return self.cursor.execute(sql, params)
  File "/root/.virtualenvs/python1811/lib/python3.5/site-packages/django/db/utils.py", line 94, in __exit__
    six.reraise(dj_exc_type, dj_exc_value, traceback)
  File "/root/.virtualenvs/python1811/lib/python3.5/site-packages/django/utils/six.py", line 685, in reraise
    raise value.with_traceback(tb)
  File "/root/.virtualenvs/python1811/lib/python3.5/site-packages/django/db/backends/utils.py", line 65, in execute
    return self.cursor.execute(sql, params)
  File "/root/.virtualenvs/python1811/lib/python3.5/site-packages/django/db/backends/mysql/base.py", line 101, in execute
    return self.cursor.execute(query, args)
  File "/root/.virtualenvs/python1811/lib/python3.5/site-packages/pymysql/cursors.py", line 170, in execute
    result = self._query(query)
  File "/root/.virtualenvs/python1811/lib/python3.5/site-packages/pymysql/cursors.py", line 328, in _query
    conn.query(q)
  File "/root/.virtualenvs/python1811/lib/python3.5/site-packages/pymysql/connections.py", line 517, in query
    self._affected_rows = self._read_query_result(unbuffered=unbuffered)
  File "/root/.virtualenvs/python1811/lib/python3.5/site-packages/pymysql/connections.py", line 732, in _read_query_result
    result.read()
  File "/root/.virtualenvs/python1811/lib/python3.5/site-packages/pymysql/connections.py", line 1075, in read
    first_packet = self.connection._read_packet()
  File "/root/.virtualenvs/python1811/lib/python3.5/site-packages/pymysql/connections.py", line 684, in _read_packet
    packet.check_error()
  File "/root/.virtualenvs/python1811/lib/python3.5/site-packages/pymysql/protocol.py", line 220, in check_error
    err.raise_mysql_exception(self._data)
  File "/root/.virtualenvs/python1811/lib/python3.5/site-packages/pymysql/err.py", line 109, in raise_mysql_exception
    raise errorclass(errno, errval)
django.db.utils.ProgrammingError: (1146, "Table 'szpython1811axf.axf_order' doesn't exist")
[pid: 22031|app: 0|req: 18/18] 113.87.160.245 () {44 vars in 762 bytes} [Fri Jan 18 07:06:51 2019] GET /axf/generateorder/ => generated 17337 bytes in 35 msecs (HTTP/1.1 500) 4 headers in 130 bytes (1 switches on core 0)
Forbidden (CSRF cookie not set.): /axf/appnotify/
[pid: 22031|app: 0|req: 19/19] 140.205.118.164 () {34 vars in 501 bytes} [Fri Jan 18 07:09:03 2019] POST /axf/appnotify/ => generated 2857 bytes in 3 msecs (HTTP/1.1 403) 3 headers in 102 bytes (1 switches on core 0)
[pid: 22031|app: 0|req: 20/20] 113.87.161.170 () {42 vars in 756 bytes} [Fri Jan 18 07:10:01 2019] GET /axf/cart/ => generated 7017 bytes in 26 msecs (HTTP/1.1 200) 4 headers in 124 bytes (1 switches on core 0)
[pid: 22031|app: 0|req: 21/21] 113.87.161.170 () {44 vars in 785 bytes} [Fri Jan 18 07:10:11 2019] GET /axf/changecartstatus/?cartid=3 => generated 78 bytes in 9 msecs (HTTP/1.1 200) 3 headers in 100 bytes (1 switches on core 0)
[pid: 22031|app: 0|req: 22/22] 113.87.161.170 () {44 vars in 762 bytes} [Fri Jan 18 07:10:14 2019] GET /axf/generateorder/ => generated 95 bytes in 36 msecs (HTTP/1.1 200) 4 headers in 114 bytes (1 switches on core 0)
[pid: 22031|app: 0|req: 23/23] 113.87.161.170 () {44 vars in 874 bytes} [Fri Jan 18 07:10:14 2019] GET /axf/orderdetail/15477954140.34805350802652113/ => generated 2788 bytes in 15 msecs (HTTP/1.1 200) 3 headers in 110 bytes (1 switches on core 0)
[pid: 22031|app: 0|req: 24/24] 113.87.161.170 () {44 vars in 860 bytes} [Fri Jan 18 07:10:17 2019] GET /axf/pay/?identifier=15477954140.34805350802652113 => generated 897 bytes in 12 msecs (HTTP/1.1 200) 3 headers in 101 bytes (1 switches on core 0)
Forbidden (CSRF cookie not set.): /axf/appnotify/
[pid: 22031|app: 0|req: 25/25] 140.205.118.83 () {34 vars in 500 bytes} [Fri Jan 18 07:11:46 2019] POST /axf/appnotify/ => generated 2857 bytes in 3 msecs (HTTP/1.1 403) 3 headers in 102 bytes (1 switches on core 0)
[pid: 22031|app: 0|req: 26/26] 113.87.160.245 () {42 vars in 2101 bytes} [Fri Jan 18 07:11:57 2019] GET /axf/returnview/?charset=utf-8&out_trade_no=15477954140.34805350802652113&method=alipay.trade.page.pay.return&total_amount=53.90&sign=tIXwg%2FocFmyglNXfFihe4Ss2Arg33TSq%2F%2Ft1OjpY3zbHmhwFnx3MpuYblgarsYRKFCvkZu82x7QW3QWkIdB%2BYLKGOpqGOVMw%2B1SLnkzYaaBouFrbn%2Fs454WDVnHPSvApws%2Fc38Lv1xhblhMBg9HfWTzxxnTfJoMoSEY1dlCqaAl0Ow7uGuLjgra9dx447LbQYqKlB4x5ou076tydnO%2B8%2Fy%2BZBvzia05vsrVpiLFTCfk9vavcbEZZ3jkpJLwQaGA9k%2FXfu7wGyzfFwAPrfIKRgbBu2jjDuTsxihQ3FCsuypbiPHlvzmGuiTQgcXeXvhnjJcEk2cjmbLkg2BVB1fhWxQ%3D%3D&trade_no=2019011822001438720500985006&auth_app_id=2016091800542542&version=1.0&app_id=2016091800542542&sign_type=RSA2&seller_id=2088102176233911&timestamp=2019-01-18+15%3A11%3A54 => generated 0 bytes in 1 msecs (HTTP/1.1 302) 4 headers in 132 bytes (1 switches on core 0)
[pid: 22031|app: 0|req: 27/27] 113.87.161.170 () {42 vars in 756 bytes} [Fri Jan 18 07:11:57 2019] GET /axf/mine/ => generated 5847 bytes in 11 msecs (HTTP/1.1 200) 4 headers in 124 bytes (1 switches on core 0)
[pid: 22031|app: 0|req: 28/28] 113.87.161.170 () {42 vars in 756 bytes} [Fri Jan 18 07:12:19 2019] GET /axf/mine/ => generated 5847 bytes in 17 msecs (HTTP/1.1 200) 4 headers in 124 bytes (1 switches on core 0)
Forbidden (CSRF cookie not set.): /axf/appnotify/
[pid: 22031|app: 0|req: 29/29] 140.205.118.141 () {34 vars in 501 bytes} [Fri Jan 18 07:15:26 2019] POST /axf/appnotify/ => generated 2857 bytes in 3 msecs (HTTP/1.1 403) 3 headers in 102 bytes (1 switches on core 0)
Not Found: /
[pid: 22031|app: 0|req: 30/30] 179.191.233.244 () {32 vars in 451 bytes} [Fri Jan 18 07:18:32 2019] GET / => generated 2022 bytes in 4 msecs (HTTP/1.1 404) 3 headers in 102 bytes (1 switches on core 0)
[pid: 22031|app: 0|req: 31/31] 113.87.161.170 () {42 vars in 756 bytes} [Fri Jan 18 07:18:41 2019] GET /axf/mine/ => generated 5847 bytes in 11 msecs (HTTP/1.1 200) 4 headers in 124 bytes (1 switches on core 0)
Invalid HTTP_HOST header: ''. The domain name provided is not valid according to RFC 1034/1035.
[pid: 22031|app: 0|req: 32/32] 91.207.172.194 () {26 vars in 269 bytes} [Fri Jan 18 08:01:01 2019] GET / => generated 55080 bytes in 47 msecs (HTTP/1.0 400) 1 headers in 53 bytes (1 switches on core 0)
*** Starting uWSGI 2.0.17.1 (64bit) on [Fri Jan 18 16:05:36 2019] ***
compiled with version: 5.4.0 20160609 on 17 January 2019 07:08:11
os: Linux-4.4.0-117-generic #141-Ubuntu SMP Tue Mar 13 11:58:07 UTC 2018
nodename: iZwz9fs05owv1cc2dm7nomZ
machine: x86_64
clock source: unix
detected number of CPU cores: 1
current working directory: /var/www/AXF
writing pidfile to uwsgi.pid
detected binary path: /root/.virtualenvs/python1811/bin/uwsgi
!!! no internal routing support, rebuild with pcre support !!!
uWSGI running as root, you can use --uid/--gid/--chroot options
*** WARNING: you are running uWSGI as root !!! (use the --uid flag) *** 
chdir() to /var/www/AXF
*** WARNING: you are running uWSGI without its master process manager ***
your processes number limit is 3824
your memory page size is 4096 bytes
detected max file descriptor number: 65535
lock engine: pthread robust mutexes
thunder lock: disabled (you can enable it with --thunder-lock)
uwsgi socket 0 bound to TCP address 0.0.0.0:8000 fd 3
uWSGI running as root, you can use --uid/--gid/--chroot options
*** WARNING: you are running uWSGI as root !!! (use the --uid flag) *** 
Python version: 3.5.2 (default, Nov 12 2018, 13:43:14)  [GCC 5.4.0 20160609]
Python main interpreter initialized at 0x12402a0
uWSGI running as root, you can use --uid/--gid/--chroot options
*** WARNING: you are running uWSGI as root !!! (use the --uid flag) *** 
python threads support enabled
your server socket listen backlog is limited to 100 connections
your mercy for graceful operations on workers is 60 seconds
mapped 72904 bytes (71 KB) for 1 cores
*** Operational MODE: single process ***
WSGI app 0 (mountpoint='') ready in 0 seconds on interpreter 0x12402a0 pid: 22274 (default app)
uWSGI running as root, you can use --uid/--gid/--chroot options
*** WARNING: you are running uWSGI as root !!! (use the --uid flag) *** 
*** uWSGI is running in multiple interpreter mode ***
spawned uWSGI worker 1 (and the only) (pid: 22274, cores: 1)
[pid: 22274|app: 0|req: 1/1] 113.87.160.245 () {42 vars in 756 bytes} [Fri Jan 18 08:05:46 2019] GET /axf/mine/ => generated 6225 bytes in 259 msecs (HTTP/1.1 200) 4 headers in 124 bytes (1 switches on core 0)
[pid: 22274|app: 0|req: 2/2] 113.87.160.245 () {40 vars in 623 bytes} [Fri Jan 18 08:06:13 2019] GET /axf/mine/ => generated 6236 bytes in 7 msecs (HTTP/1.1 200) 4 headers in 124 bytes (1 switches on core 0)
Not Found: /favicon.ico
[pid: 22274|app: 0|req: 3/3] 113.87.161.170 () {38 vars in 592 bytes} [Fri Jan 18 08:06:14 2019] GET /favicon.ico => generated 2070 bytes in 5 msecs (HTTP/1.1 404) 3 headers in 102 bytes (1 switches on core 0)
[pid: 22274|app: 0|req: 4/4] 113.87.161.170 () {42 vars in 669 bytes} [Fri Jan 18 08:06:20 2019] GET /axf/login/ => generated 2411 bytes in 6 msecs (HTTP/1.1 200) 5 headers in 278 bytes (1 switches on core 0)
[pid: 22274|app: 0|req: 5/5] 113.87.161.170 () {48 vars in 876 bytes} [Fri Jan 18 08:06:29 2019] POST /axf/login/ => generated 0 bytes in 22 msecs (HTTP/1.1 302) 6 headers in 277 bytes (1 switches on core 0)
[pid: 22274|app: 0|req: 6/6] 113.87.161.170 () {44 vars in 801 bytes} [Fri Jan 18 08:06:29 2019] GET /axf/mine/ => generated 6225 bytes in 15 msecs (HTTP/1.1 200) 4 headers in 124 bytes (1 switches on core 0)
[pid: 22274|app: 0|req: 7/7] 113.87.161.170 () {44 vars in 814 bytes} [Fri Jan 18 08:06:35 2019] GET /axf/orderlist/0/ => generated 1427 bytes in 9 msecs (HTTP/1.1 200) 3 headers in 110 bytes (1 switches on core 0)
[pid: 22274|app: 0|req: 8/8] 113.87.161.170 () {44 vars in 881 bytes} [Fri Jan 18 08:06:37 2019] GET /axf/orderdetail/15477954140.34805350802652113/ => generated 2788 bytes in 19 msecs (HTTP/1.1 200) 3 headers in 110 bytes (1 switches on core 0)
[pid: 22274|app: 0|req: 9/9] 113.87.161.170 () {44 vars in 860 bytes} [Fri Jan 18 08:06:41 2019] GET /axf/pay/?identifier=15477954140.34805350802652113 => generated 897 bytes in 12 msecs (HTTP/1.1 200) 3 headers in 101 bytes (1 switches on core 0)
[pid: 22274|app: 0|req: 10/10] 113.87.161.170 () {44 vars in 800 bytes} [Fri Jan 18 08:07:04 2019] GET /axf/cart/ => generated 5464 bytes in 37 msecs (HTTP/1.1 200) 4 headers in 124 bytes (1 switches on core 0)
[pid: 22274|app: 0|req: 11/11] 113.87.161.170 () {44 vars in 785 bytes} [Fri Jan 18 08:07:06 2019] GET /axf/changecartstatus/?cartid=4 => generated 78 bytes in 8 msecs (HTTP/1.1 200) 3 headers in 100 bytes (1 switches on core 0)
[pid: 22274|app: 0|req: 12/12] 113.87.161.170 () {44 vars in 785 bytes} [Fri Jan 18 08:07:07 2019] GET /axf/changecartstatus/?cartid=5 => generated 78 bytes in 8 msecs (HTTP/1.1 200) 3 headers in 100 bytes (1 switches on core 0)
[pid: 22274|app: 0|req: 13/13] 113.87.161.170 () {44 vars in 785 bytes} [Fri Jan 18 08:07:08 2019] GET /axf/changecartstatus/?cartid=6 => generated 78 bytes in 8 msecs (HTTP/1.1 200) 3 headers in 100 bytes (1 switches on core 0)
[pid: 22274|app: 0|req: 14/14] 113.87.161.170 () {44 vars in 762 bytes} [Fri Jan 18 08:07:10 2019] GET /axf/generateorder/ => generated 94 bytes in 54 msecs (HTTP/1.1 200) 4 headers in 114 bytes (1 switches on core 0)
[pid: 22274|app: 0|req: 15/15] 113.87.161.170 () {44 vars in 872 bytes} [Fri Jan 18 08:07:10 2019] GET /axf/orderdetail/15477988300.6260414050156342/ => generated 3396 bytes in 17 msecs (HTTP/1.1 200) 3 headers in 110 bytes (1 switches on core 0)
[pid: 22274|app: 0|req: 16/16] 113.87.161.170 () {44 vars in 857 bytes} [Fri Jan 18 08:07:12 2019] GET /axf/pay/?identifier=15477988300.6260414050156342 => generated 900 bytes in 14 msecs (HTTP/1.1 200) 3 headers in 101 bytes (1 switches on core 0)
Forbidden (CSRF cookie not set.): /axf/appnotify/
[pid: 22274|app: 0|req: 17/17] 140.205.118.99 () {34 vars in 500 bytes} [Fri Jan 18 08:08:00 2019] POST /axf/appnotify/ => generated 2857 bytes in 3 msecs (HTTP/1.1 403) 3 headers in 102 bytes (1 switches on core 0)
Internal Server Error: /axf/returnview/
Traceback (most recent call last):
  File "/root/.virtualenvs/python1811/lib/python3.5/site-packages/django/core/handlers/exception.py", line 41, in inner
    response = get_response(request)
  File "/root/.virtualenvs/python1811/lib/python3.5/site-packages/django/core/handlers/base.py", line 187, in _get_response
    response = self.process_exception_by_middleware(e, request)
  File "/root/.virtualenvs/python1811/lib/python3.5/site-packages/django/core/handlers/base.py", line 185, in _get_response
    response = wrapped_callback(request, *callback_args, **callback_kwargs)
  File "./app/views.py", line 374, in returnview
    return redirect('axf:orderlist')
  File "/root/.virtualenvs/python1811/lib/python3.5/site-packages/django/shortcuts.py", line 56, in redirect
    return redirect_class(resolve_url(to, *args, **kwargs))
  File "/root/.virtualenvs/python1811/lib/python3.5/site-packages/django/shortcuts.py", line 147, in resolve_url
    return reverse(to, args=args, kwargs=kwargs)
  File "/root/.virtualenvs/python1811/lib/python3.5/site-packages/django/urls/base.py", line 91, in reverse
    return force_text(iri_to_uri(resolver._reverse_with_prefix(view, prefix, *args, **kwargs)))
  File "/root/.virtualenvs/python1811/lib/python3.5/site-packages/django/urls/resolvers.py", line 497, in _reverse_with_prefix
    raise NoReverseMatch(msg)
django.urls.exceptions.NoReverseMatch: Reverse for 'orderlist' with no arguments not found. 1 pattern(s) tried: ['axf/orderlist/(\\d+)/$']
[pid: 22274|app: 0|req: 18/18] 113.87.161.170 () {42 vars in 2107 bytes} [Fri Jan 18 08:08:12 2019] GET /axf/returnview/?charset=utf-8&out_trade_no=15477988300.6260414050156342&method=alipay.trade.page.pay.return&total_amount=93.00&sign=oaTJZPDeswBfEbQGkBND8w8DDOWGMdz8lw6TlL25Sp73TZtTBqUBx2vazVi5sI6pFLSgfF%2FRsxsiY20S5UzZeCJ5hfrGXp4NCg6ZpZE%2FWS1CsMnI74lO%2F8ttTx1j%2FzfhrJJuTIHJ503Z1wiDZoXHer91ynI%2FCTLn8W0de2fVhnBi5hTo7MJHJBZQnVQ%2BnFJ73cKBB16xdIJ15ISVUrYYi%2FUGJr2jh%2BllGiiTVm4o0maDuYH3ljuGVxAI4yvP%2BevAfo7B2MK%2F1BW3%2FVu8JRLatEIqeyV2Qk87%2F%2FGRndFRjRDuuZMU8zzix0eg0oKYVeBmfOnRPXhMFAs8dGPedC1D2Q%3D%3D&trade_no=2019011822001416700501217055&auth_app_id=2016091800542542&version=1.0&app_id=2016091800542542&sign_type=RSA2&seller_id=2088102176233911&timestamp=2019-01-18+16%3A08%3A08 => generated 88552 bytes in 86 msecs (HTTP/1.1 500) 4 headers in 129 bytes (1 switches on core 0)
Not Found: /
[pid: 22274|app: 0|req: 19/19] 110.52.29.26 () {28 vars in 291 bytes} [Fri Jan 18 08:10:13 2019] GET / => generated 2019 bytes in 4 msecs (HTTP/1.1 404) 3 headers in 102 bytes (1 switches on core 0)
